Workbook

Sheet FTC Candidates
A1: Tahap 1. Kemunculan frequent term pada beberapa dokumen
A2: FTC Iterasi 1, minimum support = 8 dokumen, jumlah kandidat = 141
A4: No Cluster | B4: Frequent term set | C4: Cluster candidate | D4: Support | E4: EO Python | F4: EO Excel | G4: Selisih
A5: 1 | B5: {adil} | C5: {D13,D16,D36,D38,D39,D40,D61,D68,D77,D107,D108,D140,D148,D162,D177,D184,D191,D200,D208,D213,D217,D240,D243,D252,D258,D269,D297,D303,D331,D357,D366,D389,D396,D404,D429,D437,D443,D485} | D5: 38 | E5: 10.209697 | F5: ='EO Validation'!E8 -> 10.209697 | G5: =ABS(E5-F5) -> 3.6444575e-07
A6: 2 | B6: {allah} | C6: {D11,D34,D38,D39,D41,D43,D52,D68,D100,D111,D162,D181,D189,D190,D207,D228,D239,D303,D322,D352,D357,D394,D396,D399,D408,D442,D455,D486} | D6: 28 | E6: 6.90004 | F6: ='EO Validation'!E9 -> 6.90004 | G6: =ABS(E6-F6) -> 9.3103942e-09
A7: 3 | B7: {alloh} | C7: {D16,D22,D86,D118,D171,D187,D279,D299,D304,D326,D357,D369} | D7: 12 | E7: 3.680216 | F7: ='EO Validation'!E10 -> 3.6802157 | G7: =ABS(E7-F7) -> 2.7333394e-07
A8: 4 | B8: {anak} | C8: {D29,D150,D162,D187,D194,D241,D258,D261,D270,D365,D388,D401,D417,D434} | D8: 14 | E8: 4.021828 | F8: ='EO Validation'!E11 -> 4.0218277 | G8: =ABS(E8-F8) -> 2.8568913e-07
A9: 5 | B9: {aneh} | C9: {D5,D85,D88,D148,D220,D295,D406,D411} | D9: 8 | E9: 1.976066 | F9: ='EO Validation'!E12 -> 1.9760656 | G9: =ABS(E9-F9) -> 4.1070365e-07
A10: 6 | B10: {apa} | C10: {D21,D62,D80,D85,D118,D160,D163,D176,D189,D190,D209,D235,D239,D270,D335,D336,D367,D419,D425,D490,D494} | D10: 21 | E10: 5.832703 | F10: ='EO Validation'!E13 -> 5.8327031 | G10: =ABS(E10-F10) -> 1.0909427e-07
A11: 7 | B11: {baik} | C11: {D14,D19,D40,D48,D68,D101,D132,D173,D207,D259,D264,D318,D346,D373,D453,D483} | D11: 16 | E11: 4.273662 | F11: ='EO Validation'!E14 -> 4.2736624 | G11: =ABS(E11-F11) -> 3.7174091e-07
A12: 8 | B12: {bang} | C12: {D28,D66,D126,D140,D188,D234,D243,D263,D296,D324,D394,D484} | D12: 12 | E12: 3.977862 | F12: ='EO Validation'!E15 -> 3.9778621 | G12: =ABS(E12-F12) -> 8.4890051e-08
A13: 9 | B13: {banyak} | C13: {D30,D60,D95,D113,D132,D156,D183,D186,D209,D218,D239,D270,D364,D413,D434,D494} | D13: 16 | E13: 4.192626 | F13: ='EO Validation'!E16 -> 4.192626 | G13: =ABS(E13-F13) -> 4.7074562e-08
A14: 10 | B14: {bapak} | C14: {D14,D26,D36,D40,D43,D85,D170,D187,D248,D264,D294,D298,D346,D351,D357,D417,D419,D429,D493} | D14: 19 | E14: 5.145675 | F14: ='EO Validation'!E17 -> 5.1456747 | G14: =ABS(E14-F14) -> 2.7594192e-07
A15: 11 | B15: {bayar} | C15: {D80,D124,D130,D154,D174,D384,D387,D451} | D15: 8 | E15: 2.633507 | F15: ='EO Validation'!E18 -> 2.6335074 | G15: =ABS(E15-F15) -> 4.3713483e-07
A16: 12 | B16: {bebas} | C16: {D43,D77,D89,D98,D151,D172,D213,D256,D429,D462} | D16: 10 | E16: 2.641814 | F16: ='EO Validation'!E19 -> 2.641814 | G16: =ABS(E16-F16) -> 1.7398567e-09
... A145: 141 | B145: {pak, siapa} | C145: {D21,D40,D59,D112,D170,D298,D322,D401,D416,D454} | D145: 10 | E145: 2.218963 | F145: ='EO Validation'!E148 -> 2.2189625 | G145: =ABS(E145-F145) -> 4.6425738e-07

Sheet EO Validation
A1: Tahap 2. Penerapan Persamaan Entropy Overlap (EO)
A2: EO dihitung dengan kontribusi per dokumen: ((-1/f_d) * LN(1/f_d)); f_d adalah jumlah kandidat cluster yang memuat dokumen D tersebut.
A4: Frekuensi dokumen f_d | F4: =SUM(F$8:F$148) -> 2 | G4: =SUM(G$8:G$148) -> 0 | H4: =SUM(H$8:H$148) -> 10 | I4: =SUM(I$8:I$148) -> 2 | J4: =SUM(J$8:J$148) -> 4 | K4: =SUM(K$8:K$148) -> 5 | L4: =SUM(L$8:L$148) -> 7 | M4: =SUM(M$8:M$148) -> 3 | ... SK4: =SUM(SK$8:SK$148) -> 3
A5: Kontribusi EO per dokumen | F5: =IF(F$4>1,((-1/F$4)*LN(1/F$4)),0) -> 0.34657359 | G5: =IF(G$4>1,((-1/G$4)*LN(1/G$4)),0) -> 0 | H5: =IF(H$4>1,((-1/H$4)*LN(1/H$4)),0) -> 0.23025851 | I5: =IF(I$4>1,((-1/I$4)*LN(1/I$4)),0) -> 0.34657359 | J5: =IF(J$4>1,((-1/J$4)*LN(1/J$4)),0) -> 0.34657359 | K5: =IF(K$4>1,((-1/K$4)*LN(1/K$4)),0) -> 0.32188758 | L5: =IF(L$4>1,((-1/L$4)*LN(1/L$4)),0) -> 0.27798716 | M5: =IF(M$4>1,((-1/M$4)*LN(1/M$4)),0) -> 0.3662041 | ... SK5: =IF(SK$4>1,((-1/SK$4)*LN(1/SK$4)),0) -> 0.3662041
A7: No Cluster | B7: Frequent term set | C7: Cluster candidate | D7: Support | E7: EO Excel | F7: D1 | G7: D2 | H7: D3 | I7: D4 | J7: D5 | K7: D6 | L7: D7 | M7: D8 | N7: D9 | O7: D10 | P7: D11 | Q7: D12 | R7: D13 | S7: D14 | T7: D15 | U7: D16 | V7: D17 | W7: D18 | X7: D19 | Y7: D20 | Z7: D21 | AA7: D22 | AB7: D23 | AC7: D24 | AD7: D25 | AE7: D26 | AF7: D27 | AG7: D28 | AH7: D29 | AI7: D30 | AJ7: D31 | AK7: D32 | AL7: D33 | AM7: D34 | AN7: D35 | AO7: D36 | AP7: D37 | AQ7: D38 | AR7: D39 | AS7: D40 | AT7: D41 | AU7: D42 | AV7: D43 | AW7: D44 | AX7: D45 | AY7: D46 | AZ7: D47 | BA7: D48 | BB7: D49 | BC7: D50 | BD7: D51 | BE7: D52 | BF7: D53 | BG7: D54 | BH7: D55 | BI7: D56 | BJ7: D57 | BK7: D58 | BL7: D59 | BM7: D60 | BN7: D61 | BO7: D62 | BP7: D63 | BQ7: D64 | BR7: D65 | BS7: D66 | BT7: D67 | BU7: D68 | BV7: D69 | BW7: D70 | BX7: D71 | BY7: D72 | BZ7: D73 | CA7: D74 | CB7: D75 | CC7: D76 | CD7: D77 | CE7: D78 | CF7: D79 | CG7: D80 | CH7: D81 | CI7: D82 | CJ7: D83 | CK7: D84 | CL7: D85 | CM7: D86 | CN7: D87 | CO7: D88 | CP7: D89 | CQ7: D90 | CR7: D91 | CS7: D92 | CT7: D93 | CU7: D94 | CV7: D95 | CW7: D96 | CX7: D97 | CY7: D98 | CZ7: D99 | DA7: D100 | DB7: D101 | DC7: D102 | DD7: D103 | DE7: D104 | DF7: D105 | DG7: D106 | DH7: D107 | DI7: D108 | DJ7: D109 | DK7: D110 | DL7: D111 | DM7: D112 | DN7: D113 | DO7: D114 | DP7: D115 | DQ7: D116 | DR7: D117 | DS7: D118 | DT7: D119 | DU7: D120 | DV7: D121 | DW7: D122 | DX7: D123 | DY7: D124 | DZ7: D125 | EA7: D126 | EB7: D127 | EC7: D128 | ED7: D129 | EE7: D130 | EF7: D131 | EG7: D132 | EH7: D133 | EI7: D134 | EJ7: D135 | EK7: D136 | EL7: D137 | EM7: D138 | EN7: D139 | EO7: D140 | EP7: D141 | EQ7: D142 | ER7: D143 | ES7: D144 | ET7: D145 | EU7: D146 | EV7: D147 | EW7: D148 | EX7: D149 | EY7: D150 | EZ7: D151 | FA7: D152 | FB7: D153 | FC7: D154 | FD7: D155 | FE7: D156 | FF7: D157 | FG7: D158 | FH7: D159 | FI7: D160 | FJ7: D161 | FK7: D162 | FL7: D163 | FM7: D164 | FN7: D165 | FO7: D166 | FP7: D167 | FQ7: D168 | FR7: D169 | FS7: D170 | FT7: D171 | FU7: D172 | FV7: D173 | FW7: D174 | FX7: D175 | FY7: D176 | FZ7: D177 | GA7: D178 | GB7: D179 | GC7: D180 | GD7: D181 | GE7: D182 | GF7: D183 | GG7: D184 | GH7: D185 | GI7: D186 | GJ7: D187 | GK7: D188 | GL7: D189 | GM7: D190 | GN7: D191 | GO7: D192 | GP7: D193 | GQ7: D194 | GR7: D195 | GS7: D196 | GT7: D197 | GU7: D198 | GV7: D199 | GW7: D200 | GX7: D201 | GY7: D202 | GZ7: D203 | HA7: D204 | HB7: D205 | HC7: D206 | HD7: D207 | HE7: D208 | HF7: D209 | HG7: D210 | HH7: D211 | HI7: D212 | HJ7: D213 | HK7: D214 | HL7: D215 | HM7: D216 | HN7: D217 | HO7: D218 | HP7: D219 | HQ7: D220 | HR7: D221 | HS7: D222 | HT7: D223 | HU7: D224 | HV7: D225 | HW7: D226 | HX7: D227 | HY7: D228 | HZ7: D229 | IA7: D230 | IB7: D231 | IC7: D232 | ID7: D233 | IE7: D234 | IF7: D235 | IG7: D236 | IH7: D237 | II7: D238 | IJ7: D239 | IK7: D240 | IL7: D241 | IM7: D242 | IN7: D243 | IO7: D244 | IP7: D245 | IQ7: D246 | IR7: D247 | IS7: D248 | IT7: D249 | IU7: D250 | IV7: D251 | IW7: D252 | IX7: D253 | IY7: D254 | IZ7: D255 | JA7: D256 | JB7: D257 | JC7: D258 | JD7: D259 | JE7: D260 | JF7: D261 | JG7: D262 | JH7: D263 | JI7: D264 | JJ7: D265 | JK7: D266 | JL7: D267 | JM7: D268 | JN7: D269 | JO7: D270 | JP7: D271 | JQ7: D272 | JR7: D273 | JS7: D274 | JT7: D275 | JU7: D276 | JV7: D277 | JW7: D278 | JX7: D279 | JY7: D280 | JZ7: D281 | KA7: D282 | KB7: D283 | KC7: D284 | KD7: D285 | KE7: D286 | KF7: D287 | KG7: D288 | KH7: D289 | KI7: D290 | KJ7: D291 | KK7: D292 | KL7: D293 | KM7: D294 | KN7: D295 | KO7: D296 | KP7: D297 | KQ7: D298 | KR7: D299 | KS7: D300 | KT7: D301 | KU7: D302 | KV7: D303 | KW7: D304 | KX7: D305 | KY7: D306 | KZ7: D307 | LA7: D308 | LB7: D309 | LC7: D310 | LD7: D311 | LE7: D312 | LF7: D313 | LG7: D314 | LH7: D315 | LI7: D316 | LJ7: D317 | LK7: D318 | LL7: D319 | LM7: D320 | LN7: D321 | LO7: D322 | LP7: D323 | LQ7: D324 | LR7: D325 | LS7: D326 | LT7: D327 | LU7: D328 | LV7: D329 | LW7: D330 | LX7: D331 | LY7: D332 | LZ7: D333 | MA7: D334 | MB7: D335 | MC7: D336 | MD7: D337 | ME7: D338 | MF7: D339 | MG7: D340 | MH7: D341 | MI7: D342 | MJ7: D343 | MK7: D344 | ML7: D345 | MM7: D346 | MN7: D347 | MO7: D348 | MP7: D349 | MQ7: D350 | MR7: D351 | MS7: D352 | MT7: D353 | MU7: D354 | MV7: D355 | MW7: D356 | MX7: D357 | MY7: D358 | MZ7: D359 | NA7: D360 | NB7: D361 | NC7: D362 | ND7: D363 | NE7: D364 | NF7: D365 | NG7: D366 | NH7: D367 | NI7: D368 | NJ7: D369 | NK7: D370 | NL7: D371 | NM7: D372 | NN7: D373 | NO7: D374 | NP7: D375 | NQ7: D376 | NR7: D377 | NS7: D378 | NT7: D379 | NU7: D380 | NV7: D381 | NW7: D382 | NX7: D383 | NY7: D384 | NZ7: D385 | OA7: D386 | OB7: D387 | OC7: D388 | OD7: D389 | OE7: D390 | OF7: D391 | OG7: D392 | OH7: D393 | OI7: D394 | OJ7: D395 | OK7: D396 | OL7: D397 | OM7: D398 | ON7: D399 | OO7: D400 | OP7: D401 | OQ7: D402 | OR7: D403 | OS7: D404 | OT7: D405 | OU7: D406 | OV7: D407 | OW7: D408 | OX7: D409 | OY7: D410 | OZ7: D411 | PA7: D412 | PB7: D413 | PC7: D414 | PD7: D415 | PE7: D416 | PF7: D417 | PG7: D418 | PH7: D419 | PI7: D420 | PJ7: D421 | PK7: D422 | PL7: D423 | PM7: D424 | PN7: D425 | PO7: D426 | PP7: D427 | PQ7: D428 | PR7: D429 | PS7: D430 | PT7: D431 | PU7: D432 | PV7: D433 | PW7: D434 | PX7: D435 | PY7: D436 | PZ7: D437 | QA7: D438 | QB7: D439 | QC7: D440 | QD7: D441 | QE7: D442 | QF7: D443 | QG7: D444 | QH7: D445 | QI7: D446 | QJ7: D447 | QK7: D448 | QL7: D449 | QM7: D450 | QN7: D451 | QO7: D452 | QP7: D453 | QQ7: D454 | QR7: D455 | QS7: D456 | QT7: D457 | QU7: D458 | QV7: D459 | QW7: D460 | QX7: D461 | QY7: D462 | QZ7: D463 | RA7: D464 | RB7: D465 | RC7: D466 | RD7: D467 | RE7: D468 | RF7: D469 | RG7: D470 | RH7: D471 | RI7: D472 | RJ7: D473 | RK7: D474 | RL7: D475 | RM7: D476 | RN7: D477 | RO7: D478 | RP7: D479 | RQ7: D480 | RR7: D481 | RS7: D482 | RT7: D483 | RU7: D484 | RV7: D485 | RW7: D486 | RX7: D487 | RY7: D488 | RZ7: D489 | SA7: D490 | SB7: D491 | SC7: D492 | SD7: D493 | SE7: D494 | SF7: D495 | SG7: D496 | SH7: D497 | SI7: D498 | SJ7: D499 | SK7: D500
A8: 1 | B8: {adil} | C8: {D13,D16,D36,D38,D39,D40,D61,D68,D77,D107,D108,D140,D148,D162,D177,D184,D191,D200,D208,D213,D217,D240,D243,D252,D258,D269,D297,D303,D331,D357,D366,D389,D396,D404,D429,D437,D443,D485} | D8: =SUM(F8:SK8) -> 38 | E8: =SUMPRODUCT(F8:SK8,$F$5:$SK$5) -> 10.209697 | F8: 0 | G8: 0 | H8: 0 | I8: 0 | J8: 0 | K8: 0 | L8: 0 | M8: 0 | N8: 0 | O8: 0 | P8: 0 | Q8: 0 | R8: 1 | S8: 0 | T8: 0 | U8: 1 | V8: 0 | W8: 0 | X8: 0 | Y8: 0 | Z8: 0 | AA8: 0 | AB8: 0 | AC8: 0 | AD8: 0 | AE8: 0 | AF8: 0 | AG8: 0 | AH8: 0 | AI8: 0 | AJ8: 0 | AK8: 0 | AL8: 0 | AM8: 0 | AN8: 0 | AO8: 1 | AP8: 0 | AQ8: 1 | AR8: 1 | AS8: 1 | AT8: 0 | AU8: 0 | AV8: 0 | AW8: 0 | AX8: 0 | AY8: 0 | AZ8: 0 | BA8: 0 | BB8: 0 | BC8: 0 | BD8: 0 | BE8: 0 | BF8: 0 | BG8: 0 | BH8: 0 | BI8: 0 | BJ8: 0 | BK8: 0 | BL8: 0 | BM8: 0 | BN8: 1 | BO8: 0 | BP8: 0 | BQ8: 0 | BR8: 0 | BS8: 0 | BT8: 0 | BU8: 1 | BV8: 0 | BW8: 0 | BX8: 0 | BY8: 0 | BZ8: 0 | CA8: 0 | CB8: 0 | CC8: 0 | CD8: 1 | CE8: 0 | CF8: 0 | CG8: 0 | CH8: 0 | CI8: 0 | CJ8: 0 | CK8: 0 | CL8: 0 | CM8: 0 | CN8: 0 | CO8: 0 | CP8: 0 | CQ8: 0 | CR8: 0 | CS8: 0 | CT8: 0 | CU8: 0 | CV8: 0 | CW8: 0 | CX8: 0 | CY8: 0 | CZ8: 0 | DA8: 0 | DB8: 0 | DC8: 0 | DD8: 0 | DE8: 0 | DF8: 0 | DG8: 0 | DH8: 1 | DI8: 1 | DJ8: 0 | DK8: 0 | DL8: 0 | DM8: 0 | DN8: 0 | DO8: 0 | DP8: 0 | DQ8: 0 | DR8: 0 | DS8: 0 | DT8: 0 | DU8: 0 | DV8: 0 | DW8: 0 | DX8: 0 | DY8: 0 | DZ8: 0 | EA8: 0 | EB8: 0 | EC8: 0 | ED8: 0 | EE8: 0 | EF8: 0 | EG8: 0 | EH8: 0 | EI8: 0 | EJ8: 0 | EK8: 0 | EL8: 0 | EM8: 0 | EN8: 0 | EO8: 1 | EP8: 0 | EQ8: 0 | ER8: 0 | ES8: 0 | ET8: 0 | EU8: 0 | EV8: 0 | EW8: 1 | EX8: 0 | EY8: 0 | EZ8: 0 | FA8: 0 | FB8: 0 | FC8: 0 | FD8: 0 | FE8: 0 | FF8: 0 | FG8: 0 | FH8: 0 | FI8: 0 | FJ8: 0 | FK8: 1 | FL8: 0 | FM8: 0 | FN8: 0 | FO8: 0 | FP8: 0 | FQ8: 0 | FR8: 0 | FS8: 0 | FT8: 0 | FU8: 0 | FV8: 0 | FW8: 0 | FX8: 0 | FY8: 0 | FZ8: 1 | GA8: 0 | GB8: 0 | GC8: 0 | GD8: 0 | GE8: 0 | GF8: 0 | GG8: 1 | GH8: 0 | GI8: 0 | GJ8: 0 | GK8: 0 | GL8: 0 | GM8: 0 | GN8: 1 | GO8: 0 | GP8: 0 | GQ8: 0 | GR8: 0 | GS8: 0 | GT8: 0 | GU8: 0 | GV8: 0 | GW8: 1 | GX8: 0 | GY8: 0 | GZ8: 0 | HA8: 0 | HB8: 0 | HC8: 0 | HD8: 0 | HE8: 1 | HF8: 0 | HG8: 0 | HH8: 0 | HI8: 0 | HJ8: 1 | HK8: 0 | HL8: 0 | HM8: 0 | HN8: 1 | HO8: 0 | HP8: 0 | HQ8: 0 | HR8: 0 | HS8: 0 | HT8: 0 | HU8: 0 | HV8: 0 | HW8: 0 | HX8: 0 | HY8: 0 | HZ8: 0 | IA8: 0 | IB8: 0 | IC8: 0 | ID8: 0 | IE8: 0 | IF8: 0 | IG8: 0 | IH8: 0 | II8: 0 | IJ8: 0 | IK8: 1 | IL8: 0 | IM8: 0 | IN8: 1 | IO8: 0 | IP8: 0 | IQ8: 0 | IR8: 0 | IS8: 0 | IT8: 0 | IU8: 0 | IV8: 0 | IW8: 1 | IX8: 0 | IY8: 0 | IZ8: 0 | JA8: 0 | JB8: 0 | JC8: 1 | JD8: 0 | JE8: 0 | JF8: 0 | JG8: 0 | JH8: 0 | JI8: 0 | JJ8: 0 | JK8: 0 | JL8: 0 | JM8: 0 | JN8: 1 | JO8: 0 | JP8: 0 | JQ8: 0 | JR8: 0 | JS8: 0 | JT8: 0 | JU8: 0 | JV8: 0 | JW8: 0 | JX8: 0 | JY8: 0 | JZ8: 0 | KA8: 0 | KB8: 0 | KC8: 0 | KD8: 0 | KE8: 0 | KF8: 0 | KG8: 0 | KH8: 0 | KI8: 0 | KJ8: 0 | KK8: 0 | KL8: 0 | KM8: 0 | KN8: 0 | KO8: 0 | KP8: 1 | KQ8: 0 | KR8: 0 | KS8: 0 | KT8: 0 | KU8: 0 | KV8: 1 | KW8: 0 | KX8: 0 | KY8: 0 | KZ8: 0 | LA8: 0 | LB8: 0 | LC8: 0 | LD8: 0 | LE8: 0 | LF8: 0 | LG8: 0 | LH8: 0 | LI8: 0 | LJ8: 0 | LK8: 0 | LL8: 0 | LM8: 0 | LN8: 0 | LO8: 0 | LP8: 0 | LQ8: 0 | LR8: 0 | LS8: 0 | LT8: 0 | LU8: 0 | LV8: 0 | LW8: 0 | LX8: 1 | LY8: 0 | LZ8: 0 | MA8: 0 | MB8: 0 | MC8: 0 | MD8: 0 | ME8: 0 | MF8: 0 | MG8: 0 | MH8: 0 | MI8: 0 | MJ8: 0 | MK8: 0 | ML8: 0 | MM8: 0 | MN8: 0 | MO8: 0 | MP8: 0 | MQ8: 0 | MR8: 0 | MS8: 0 | MT8: 0 | MU8: 0 | MV8: 0 | MW8: 0 | MX8: 1 | MY8: 0 | MZ8: 0 | NA8: 0 | NB8: 0 | NC8: 0 | ND8: 0 | NE8: 0 | NF8: 0 | NG8: 1 | NH8: 0 | NI8: 0 | NJ8: 0 | NK8: 0 | NL8: 0 | NM8: 0 | NN8: 0 | NO8: 0 | NP8: 0 | NQ8: 0 | NR8: 0 | NS8: 0 | NT8: 0 | NU8: 0 | NV8: 0 | NW8: 0 | NX8: 0 | NY8: 0 | NZ8: 0 | OA8: 0 | OB8: 0 | OC8: 0 | OD8: 1 | OE8: 0 | OF8: 0 | OG8: 0 | OH8: 0 | OI8: 0 | OJ8: 0 | OK8: 1 | OL8: 0 | OM8: 0 | ON8: 0 | OO8: 0 | OP8: 0 | OQ8: 0 | OR8: 0 | OS8: 1 | OT8: 0 | OU8: 0 | OV8: 0 | OW8: 0 | OX8: 0 | OY8: 0 | OZ8: 0 | PA8: 0 | PB8: 0 | PC8: 0 | PD8: 0 | PE8: 0 | PF8: 0 | PG8: 0 | PH8: 0 | PI8: 0 | PJ8: 0 | PK8: 0 | PL8: 0 | PM8: 0 | PN8: 0 | PO8: 0 | PP8: 0 | PQ8: 0 | PR8: 1 | PS8: 0 | PT8: 0 | PU8: 0 | PV8: 0 | PW8: 0 | PX8: 0 | PY8: 0 | PZ8: 1 | QA8: 0 | QB8: 0 | QC8: 0 | QD8: 0 | QE8: 0 | QF8: 1 | QG8: 0 | QH8: 0 | QI8: 0 | QJ8: 0 | QK8: 0 | QL8: 0 | QM8: 0 | QN8: 0 | QO8: 0 | QP8: 0 | QQ8: 0 | QR8: 0 | QS8: 0 | QT8: 0 | QU8: 0 | QV8: 0 | QW8: 0 | QX8: 0 | QY8: 0 | QZ8: 0 | RA8: 0 | RB8: 0 | RC8: 0 | RD8: 0 | RE8: 0 | RF8: 0 | RG8: 0 | RH8: 0 | RI8: 0 | RJ8: 0 | RK8: 0 | RL8: 0 | RM8: 0 | RN8: 0 | RO8: 0 | RP8: 0 | RQ8: 0 | RR8: 0 | RS8: 0 | RT8: 0 | RU8: 0 | RV8: 1 | RW8: 0 | RX8: 0 | RY8: 0 | RZ8: 0 | SA8: 0 | SB8: 0 | SC8: 0 | SD8: 0 | SE8: 0 | SF8: 0 | SG8: 0 | SH8: 0 | SI8: 0 | SJ8: 0 | SK8: 0
A9: 2 | B9: {allah} | C9: {D11,D34,D38,D39,D41,D43,D52,D68,D100,D111,D162,D181,D189,D190,D207,D228,D239,D303,D322,D352,D357,D394,D396,D399,D408,D442,D455,D486} | D9: =SUM(F9:SK9) -> 28 | E9: =SUMPRODUCT(F9:SK9,$F$5:$SK$5) -> 6.90004 | F9: 0 | G9: 0 | H9: 0 | I9: 0 | J9: 0 | K9: 0 | L9: 0 | M9: 0 | N9: 0 | O9: 0 | P9: 1 | Q9: 0 | R9: 0 | S9: 0 | T9: 0 | U9: 0 | V9: 0 | W9: 0 | X9: 0 | Y9: 0 | Z9: 0 | AA9: 0 | AB9: 0 | AC9: 0 | AD9: 0 | AE9: 0 | AF9: 0 | AG9: 0 | AH9: 0 | AI9: 0 | AJ9: 0 | AK9: 0 | AL9: 0 | AM9: 1 | AN9: 0 | AO9: 0 | AP9: 0 | AQ9: 1 | AR9: 1 | AS9: 0 | AT9: 1 | AU9: 0 | AV9: 1 | AW9: 0 | AX9: 0 | AY9: 0 | AZ9: 0 | BA9: 0 | BB9: 0 | BC9: 0 | BD9: 0 | BE9: 1 | BF9: 0 | BG9: 0 | BH9: 0 | BI9: 0 | BJ9: 0 | BK9: 0 | BL9: 0 | BM9: 0 | BN9: 0 | BO9: 0 | BP9: 0 | BQ9: 0 | BR9: 0 | BS9: 0 | BT9: 0 | BU9: 1 | BV9: 0 | BW9: 0 | BX9: 0 | BY9: 0 | BZ9: 0 | CA9: 0 | CB9: 0 | CC9: 0 | CD9: 0 | CE9: 0 | CF9: 0 | CG9: 0 | CH9: 0 | CI9: 0 | CJ9: 0 | CK9: 0 | CL9: 0 | CM9: 0 | CN9: 0 | CO9: 0 | CP9: 0 | CQ9: 0 | CR9: 0 | CS9: 0 | CT9: 0 | CU9: 0 | CV9: 0 | CW9: 0 | CX9: 0 | CY9: 0 | CZ9: 0 | DA9: 1 | DB9: 0 | DC9: 0 | DD9: 0 | DE9: 0 | DF9: 0 | DG9: 0 | DH9: 0 | DI9: 0 | DJ9: 0 | DK9: 0 | DL9: 1 | DM9: 0 | DN9: 0 | DO9: 0 | DP9: 0 | DQ9: 0 | DR9: 0 | DS9: 0 | DT9: 0 | DU9: 0 | DV9: 0 | DW9: 0 | DX9: 0 | DY9: 0 | DZ9: 0 | EA9: 0 | EB9: 0 | EC9: 0 | ED9: 0 | EE9: 0 | EF9: 0 | EG9: 0 | EH9: 0 | EI9: 0 | EJ9: 0 | EK9: 0 | EL9: 0 | EM9: 0 | EN9: 0 | EO9: 0 | EP9: 0 | EQ9: 0 | ER9: 0 | ES9: 0 | ET9: 0 | EU9: 0 | EV9: 0 | EW9: 0 | EX9: 0 | EY9: 0 | EZ9: 0 | FA9: 0 | FB9: 0 | FC9: 0 | FD9: 0 | FE9: 0 | FF9: 0 | FG9: 0 | FH9: 0 | FI9: 0 | FJ9: 0 | FK9: 1 | FL9: 0 | FM9: 0 | FN9: 0 | FO9: 0 | FP9: 0 | FQ9: 0 | FR9: 0 | FS9: 0 | FT9: 0 | FU9: 0 | FV9: 0 | FW9: 0 | FX9: 0 | FY9: 0 | FZ9: 0 | GA9: 0 | GB9: 0 | GC9: 0 | GD9: 1 | GE9: 0 | GF9: 0 | GG9: 0 | GH9: 0 | GI9: 0 | GJ9: 0 | GK9: 0 | GL9: 1 | GM9: 1 | GN9: 0 | GO9: 0 | GP9: 0 | GQ9: 0 | GR9: 0 | GS9: 0 | GT9: 0 | GU9: 0 | GV9: 0 | GW9: 0 | GX9: 0 | GY9: 0 | GZ9: 0 | HA9: 0 | HB9: 0 | HC9: 0 | HD9: 1 | HE9: 0 | HF9: 0 | HG9: 0 | HH9: 0 | HI9: 0 | HJ9: 0 | HK9: 0 | HL9: 0 | HM9: 0 | HN9: 0 | HO9: 0 | HP9: 0 | HQ9: 0 | HR9: 0 | HS9: 0 | HT9: 0 | HU9: 0 | HV9: 0 | HW9: 0 | HX9: 0 | HY9: 1 | HZ9: 0 | IA9: 0 | IB9: 0 | IC9: 0 | ID9: 0 | IE9: 0 | IF9: 0 | IG9: 0 | IH9: 0 | II9: 0 | IJ9: 1 | IK9: 0 | IL9: 0 | IM9: 0 | IN9: 0 | IO9: 0 | IP9: 0 | IQ9: 0 | IR9: 0 | IS9: 0 | IT9: 0 | IU9: 0 | IV9: 0 | IW9: 0 | IX9: 0 | IY9: 0 | IZ9: 0 | JA9: 0 | JB9: 0 | JC9: 0 | JD9: 0 | JE9: 0 | JF9: 0 | JG9: 0 | JH9: 0 | JI9: 0 | JJ9: 0 | JK9: 0 | JL9: 0 | JM9: 0 | JN9: 0 | JO9: 0 | JP9: 0 | JQ9: 0 | JR9: 0 | JS9: 0 | JT9: 0 | JU9: 0 | JV9: 0 | JW9: 0 | JX9: 0 | JY9: 0 | JZ9: 0 | KA9: 0 | KB9: 0 | KC9: 0 | KD9: 0 | KE9: 0 | KF9: 0 | KG9: 0 | KH9: 0 | KI9: 0 | KJ9: 0 | KK9: 0 | KL9: 0 | KM9: 0 | KN9: 0 | KO9: 0 | KP9: 0 | KQ9: 0 | KR9: 0 | KS9: 0 | KT9: 0 | KU9: 0 | KV9: 1 | KW9: 0 | KX9: 0 | KY9: 0 | KZ9: 0 | LA9: 0 | LB9: 0 | LC9: 0 | LD9: 0 | LE9: 0 | LF9: 0 | LG9: 0 | LH9: 0 | LI9: 0 | LJ9: 0 | LK9: 0 | LL9: 0 | LM9: 0 | LN9: 0 | LO9: 1 | LP9: 0 | LQ9: 0 | LR9: 0 | LS9: 0 | LT9: 0 | LU9: 0 | LV9: 0 | LW9: 0 | LX9: 0 | LY9: 0 | LZ9: 0 | MA9: 0 | MB9: 0 | MC9: 0 | MD9: 0 | ME9: 0 | MF9: 0 | MG9: 0 | MH9: 0 | MI9: 0 | MJ9: 0 | MK9: 0 | ML9: 0 | MM9: 0 | MN9: 0 | MO9: 0 | MP9: 0 | MQ9: 0 | MR9: 0 | MS9: 1 | MT9: 0 | MU9: 0 | MV9: 0 | MW9: 0 | MX9: 1 | MY9: 0 | MZ9: 0 | NA9: 0 | NB9: 0 | NC9: 0 | ND9: 0 | NE9: 0 | NF9: 0 | NG9: 0 | NH9: 0 | NI9: 0 | NJ9: 0 | NK9: 0 | NL9: 0 | NM9: 0 | NN9: 0 | NO9: 0 | NP9: 0 | NQ9: 0 | NR9: 0 | NS9: 0 | NT9: 0 | NU9: 0 | NV9: 0 | NW9: 0 | NX9: 0 | NY9: 0 | NZ9: 0 | OA9: 0 | OB9: 0 | OC9: 0 | OD9: 0 | OE9: 0 | OF9: 0 | OG9: 0 | OH9: 0 | OI9: 1 | OJ9: 0 | OK9: 1 | OL9: 0 | OM9: 0 | ON9: 1 | OO9: 0 | OP9: 0 | OQ9: 0 | OR9: 0 | OS9: 0 | OT9: 0 | OU9: 0 | OV9: 0 | OW9: 1 | OX9: 0 | OY9: 0 | OZ9: 0 | PA9: 0 | PB9: 0 | PC9: 0 | PD9: 0 | PE9: 0 | PF9: 0 | PG9: 0 | PH9: 0 | PI9: 0 | PJ9: 0 | PK9: 0 | PL9: 0 | PM9: 0 | PN9: 0 | PO9: 0 | PP9: 0 | PQ9: 0 | PR9: 0 | PS9: 0 | PT9: 0 | PU9: 0 | PV9: 0 | PW9: 0 | PX9: 0 | PY9: 0 | PZ9: 0 | QA9: 0 | QB9: 0 | QC9: 0 | QD9: 0 | QE9: 1 | QF9: 0 | QG9: 0 | QH9: 0 | QI9: 0 | QJ9: 0 | QK9: 0 | QL9: 0 | QM9: 0 | QN9: 0 | QO9: 0 | QP9: 0 | QQ9: 0 | QR9: 1 | QS9: 0 | QT9: 0 | QU9: 0 | QV9: 0 | QW9: 0 | QX9: 0 | QY9: 0 | QZ9: 0 | RA9: 0 | RB9: 0 | RC9: 0 | RD9: 0 | RE9: 0 | RF9: 0 | RG9: 0 | RH9: 0 | RI9: 0 | RJ9: 0 | RK9: 0 | RL9: 0 | RM9: 0 | RN9: 0 | RO9: 0 | RP9: 0 | RQ9: 0 | RR9: 0 | RS9: 0 | RT9: 0 | RU9: 0 | RV9: 0 | RW9: 1 | RX9: 0 | RY9: 0 | RZ9: 0 | SA9: 0 | SB9: 0 | SC9: 0 | SD9: 0 | SE9: 0 | SF9: 0 | SG9: 0 | SH9: 0 | SI9: 0 | SJ9: 0 | SK9: 0
A10: 3 | B10: {alloh} | C10: {D16,D22,D86,D118,D171,D187,D279,D299,D304,D326,D357,D369} | D10: =SUM(F10:SK10) -> 12 | E10: =SUMPRODUCT(F10:SK10,$F$5:$SK$5) -> 3.6802157 | F10: 0 | G10: 0 | H10: 0 | I10: 0 | J10: 0 | K10: 0 | L10: 0 | M10: 0 | N10: 0 | O10: 0 | P10: 0 | Q10: 0 | R10: 0 | S10: 0 | T10: 0 | U10: 1 | V10: 0 | W10: 0 | X10: 0 | Y10: 0 | Z10: 0 | AA10: 1 | AB10: 0 | AC10: 0 | AD10: 0 | AE10: 0 | AF10: 0 | AG10: 0 | AH10: 0 | AI10: 0 | AJ10: 0 | AK10: 0 | AL10: 0 | AM10: 0 | AN10: 0 | AO10: 0 | AP10: 0 | AQ10: 0 | AR10: 0 | AS10: 0 | AT10: 0 | AU10: 0 | AV10: 0 | AW10: 0 | AX10: 0 | AY10: 0 | AZ10: 0 | BA10: 0 | BB10: 0 | BC10: 0 | BD10: 0 | BE10: 0 | BF10: 0 | BG10: 0 | BH10: 0 | BI10: 0 | BJ10: 0 | BK10: 0 | BL10: 0 | BM10: 0 | BN10: 0 | BO10: 0 | BP10: 0 | BQ10: 0 | BR10: 0 | BS10: 0 | BT10: 0 | BU10: 0 | BV10: 0 | BW10: 0 | BX10: 0 | BY10: 0 | BZ10: 0 | CA10: 0 | CB10: 0 | CC10: 0 | CD10: 0 | CE10: 0 | CF10: 0 | CG10: 0 | CH10: 0 | CI10: 0 | CJ10: 0 | CK10: 0 | CL10: 0 | CM10: 1 | CN10: 0 | CO10: 0 | CP10: 0 | CQ10: 0 | CR10: 0 | CS10: 0 | CT10: 0 | CU10: 0 | CV10: 0 | CW10: 0 | CX10: 0 | CY10: 0 | CZ10: 0 | DA10: 0 | DB10: 0 | DC10: 0 | DD10: 0 | DE10: 0 | DF10: 0 | DG10: 0 | DH10: 0 | DI10: 0 | DJ10: 0 | DK10: 0 | DL10: 0 | DM10: 0 | DN10: 0 | DO10: 0 | DP10: 0 | DQ10: 0 | DR10: 0 | DS10: 1 | DT10: 0 | DU10: 0 | DV10: 0 | DW10: 0 | DX10: 0 | DY10: 0 | DZ10: 0 | EA10: 0 | EB10: 0 | EC10: 0 | ED10: 0 | EE10: 0 | EF10: 0 | EG10: 0 | EH10: 0 | EI10: 0 | EJ10: 0 | EK10: 0 | EL10: 0 | EM10: 0 | EN10: 0 | EO10: 0 | EP10: 0 | EQ10: 0 | ER10: 0 | ES10: 0 | ET10: 0 | EU10: 0 | EV10: 0 | EW10: 0 | EX10: 0 | EY10: 0 | EZ10: 0 | FA10: 0 | FB10: 0 | FC10: 0 | FD10: 0 | FE10: 0 | FF10: 0 | FG10: 0 | FH10: 0 | FI10: 0 | FJ10: 0 | FK10: 0 | FL10: 0 | FM10: 0 | FN10: 0 | FO10: 0 | FP10: 0 | FQ10: 0 | FR10: 0 | FS10: 0 | FT10: 1 | FU10: 0 | FV10: 0 | FW10: 0 | FX10: 0 | FY10: 0 | FZ10: 0 | GA10: 0 | GB10: 0 | GC10: 0 | GD10: 0 | GE10: 0 | GF10: 0 | GG10: 0 | GH10: 0 | GI10: 0 | GJ10: 1 | GK10: 0 | GL10: 0 | GM10: 0 | GN10: 0 | GO10: 0 | GP10: 0 | GQ10: 0 | GR10: 0 | GS10: 0 | GT10: 0 | GU10: 0 | GV10: 0 | GW10: 0 | GX10: 0 | GY10: 0 | GZ10: 0 | HA10: 0 | HB10: 0 | HC10: 0 | HD10: 0 | HE10: 0 | HF10: 0 | HG10: 0 | HH10: 0 | HI10: 0 | HJ10: 0 | HK10: 0 | HL10: 0 | HM10: 0 | HN10: 0 | HO10: 0 | HP10: 0 | HQ10: 0 | HR10: 0 | HS10: 0 | HT10: 0 | HU10: 0 | HV10: 0 | HW10: 0 | HX10: 0 | HY10: 0 | HZ10: 0 | IA10: 0 | IB10: 0 | IC10: 0 | ID10: 0 | IE10: 0 | IF10: 0 | IG10: 0 | IH10: 0 | II10: 0 | IJ10: 0 | IK10: 0 | IL10: 0 | IM10: 0 | IN10: 0 | IO10: 0 | IP10: 0 | IQ10: 0 | IR10: 0 | IS10: 0 | IT10: 0 | IU10: 0 | IV10: 0 | IW10: 0 | IX10: 0 | IY10: 0 | IZ10: 0 | JA10: 0 | JB10: 0 | JC10: 0 | JD10: 0 | JE10: 0 | JF10: 0 | JG10: 0 | JH10: 0 | JI10: 0 | JJ10: 0 | JK10: 0 | JL10: 0 | JM10: 0 | JN10: 0 | JO10: 0 | JP10: 0 | JQ10: 0 | JR10: 0 | JS10: 0 | JT10: 0 | JU10: 0 | JV10: 0 | JW10: 0 | JX10: 1 | JY10: 0 | JZ10: 0 | KA10: 0 | KB10: 0 | KC10: 0 | KD10: 0 | KE10: 0 | KF10: 0 | KG10: 0 | KH10: 0 | KI10: 0 | KJ10: 0 | KK10: 0 | KL10: 0 | KM10: 0 | KN10: 0 | KO10: 0 | KP10: 0 | KQ10: 0 | KR10: 1 | KS10: 0 | KT10: 0 | KU10: 0 | KV10: 0 | KW10: 1 | KX10: 0 | KY10: 0 | KZ10: 0 | LA10: 0 | LB10: 0 | LC10: 0 | LD10: 0 | LE10: 0 | LF10: 0 | LG10: 0 | LH10: 0 | LI10: 0 | LJ10: 0 | LK10: 0 | LL10: 0 | LM10: 0 | LN10: 0 | LO10: 0 | LP10: 0 | LQ10: 0 | LR10: 0 | LS10: 1 | LT10: 0 | LU10: 0 | LV10: 0 | LW10: 0 | LX10: 0 | LY10: 0 | LZ10: 0 | MA10: 0 | MB10: 0 | MC10: 0 | MD10: 0 | ME10: 0 | MF10: 0 | MG10: 0 | MH10: 0 | MI10: 0 | MJ10: 0 | MK10: 0 | ML10: 0 | MM10: 0 | MN10: 0 | MO10: 0 | MP10: 0 | MQ10: 0 | MR10: 0 | MS10: 0 | MT10: 0 | MU10: 0 | MV10: 0 | MW10: 0 | MX10: 1 | MY10: 0 | MZ10: 0 | NA10: 0 | NB10: 0 | NC10: 0 | ND10: 0 | NE10: 0 | NF10: 0 | NG10: 0 | NH10: 0 | NI10: 0 | NJ10: 1 | NK10: 0 | NL10: 0 | NM10: 0 | NN10: 0 | NO10: 0 | NP10: 0 | NQ10: 0 | NR10: 0 | NS10: 0 | NT10: 0 | NU10: 0 | NV10: 0 | NW10: 0 | NX10: 0 | NY10: 0 | NZ10: 0 | OA10: 0 | OB10: 0 | OC10: 0 | OD10: 0 | OE10: 0 | OF10: 0 | OG10: 0 | OH10: 0 | OI10: 0 | OJ10: 0 | OK10: 0 | OL10: 0 | OM10: 0 | ON10: 0 | OO10: 0 | OP10: 0 | OQ10: 0 | OR10: 0 | OS10: 0 | OT10: 0 | OU10: 0 | OV10: 0 | OW10: 0 | OX10: 0 | OY10: 0 | OZ10: 0 | PA10: 0 | PB10: 0 | PC10: 0 | PD10: 0 | PE10: 0 | PF10: 0 | PG10: 0 | PH10: 0 | PI10: 0 | PJ10: 0 | PK10: 0 | PL10: 0 | PM10: 0 | PN10: 0 | PO10: 0 | PP10: 0 | PQ10: 0 | PR10: 0 | PS10: 0 | PT10: 0 | PU10: 0 | PV10: 0 | PW10: 0 | PX10: 0 | PY10: 0 | PZ10: 0 | QA10: 0 | QB10: 0 | QC10: 0 | QD10: 0 | QE10: 0 | QF10: 0 | QG10: 0 | QH10: 0 | QI10: 0 | QJ10: 0 | QK10: 0 | QL10: 0 | QM10: 0 | QN10: 0 | QO10: 0 | QP10: 0 | QQ10: 0 | QR10: 0 | QS10: 0 | QT10: 0 | QU10: 0 | QV10: 0 | QW10: 0 | QX10: 0 | QY10: 0 | QZ10: 0 | RA10: 0 | RB10: 0 | RC10: 0 | RD10: 0 | RE10: 0 | RF10: 0 | RG10: 0 | RH10: 0 | RI10: 0 | RJ10: 0 | RK10: 0 | RL10: 0 | RM10: 0 | RN10: 0 | RO10: 0 | RP10: 0 | RQ10: 0 | RR10: 0 | RS10: 0 | RT10: 0 | RU10: 0 | RV10: 0 | RW10: 0 | RX10: 0 | RY10: 0 | RZ10: 0 | SA10: 0 | SB10: 0 | SC10: 0 | SD10: 0 | SE10: 0 | SF10: 0 | SG10: 0 | SH10: 0 | SI10: 0 | SJ10: 0 | SK10: 0
A11: 4 | B11: {anak} | C11: {D29,D150,D162,D187,D194,D241,D258,D261,D270,D365,D388,D401,D417,D434} | D11: =SUM(F11:SK11) -> 14 | E11: =SUMPRODUCT(F11:SK11,$F$5:$SK$5) -> 4.0218277 | F11: 0 | G11: 0 | H11: 0 | I11: 0 | J11: 0 | K11: 0 | L11: 0 | M11: 0 | N11: 0 | O11: 0 | P11: 0 | Q11: 0 | R11: 0 | S11: 0 | T11: 0 | U11: 0 | V11: 0 | W11: 0 | X11: 0 | Y11: 0 | Z11: 0 | AA11: 0 | AB11: 0 | AC11: 0 | AD11: 0 | AE11: 0 | AF11: 0 | AG11: 0 | AH11: 1 | AI11: 0 | AJ11: 0 | AK11: 0 | AL11: 0 | AM11: 0 | AN11: 0 | AO11: 0 | AP11: 0 | AQ11: 0 | AR11: 0 | AS11: 0 | AT11: 0 | AU11: 0 | AV11: 0 | AW11: 0 | AX11: 0 | AY11: 0 | AZ11: 0 | BA11: 0 | BB11: 0 | BC11: 0 | BD11: 0 | BE11: 0 | BF11: 0 | BG11: 0 | BH11: 0 | BI11: 0 | BJ11: 0 | BK11: 0 | BL11: 0 | BM11: 0 | BN11: 0 | BO11: 0 | BP11: 0 | BQ11: 0 | BR11: 0 | BS11: 0 | BT11: 0 | BU11: 0 | BV11: 0 | BW11: 0 | BX11: 0 | BY11: 0 | BZ11: 0 | CA11: 0 | CB11: 0 | CC11: 0 | CD11: 0 | CE11: 0 | CF11: 0 | CG11: 0 | CH11: 0 | CI11: 0 | CJ11: 0 | CK11: 0 | CL11: 0 | CM11: 0 | CN11: 0 | CO11: 0 | CP11: 0 | CQ11: 0 | CR11: 0 | CS11: 0 | CT11: 0 | CU11: 0 | CV11: 0 | CW11: 0 | CX11: 0 | CY11: 0 | CZ11: 0 | DA11: 0 | DB11: 0 | DC11: 0 | DD11: 0 | DE11: 0 | DF11: 0 | DG11: 0 | DH11: 0 | DI11: 0 | DJ11: 0 | DK11: 0 | DL11: 0 | DM11: 0 | DN11: 0 | DO11: 0 | DP11: 0 | DQ11: 0 | DR11: 0 | DS11: 0 | DT11: 0 | DU11: 0 | DV11: 0 | DW11: 0 | DX11: 0 | DY11: 0 | DZ11: 0 | EA11: 0 | EB11: 0 | EC11: 0 | ED11: 0 | EE11: 0 | EF11: 0 | EG11: 0 | EH11: 0 | EI11: 0 | EJ11: 0 | EK11: 0 | EL11: 0 | EM11: 0 | EN11: 0 | EO11: 0 | EP11: 0 | EQ11: 0 | ER11: 0 | ES11: 0 | ET11: 0 | EU11: 0 | EV11: 0 | EW11: 0 | EX11: 0 | EY11: 1 | EZ11: 0 | FA11: 0 | FB11: 0 | FC11: 0 | FD11: 0 | FE11: 0 | FF11: 0 | FG11: 0 | FH11: 0 | FI11: 0 | FJ11: 0 | FK11: 1 | FL11: 0 | FM11: 0 | FN11: 0 | FO11: 0 | FP11: 0 | FQ11: 0 | FR11: 0 | FS11: 0 | FT11: 0 | FU11: 0 | FV11: 0 | FW11: 0 | FX11: 0 | FY11: 0 | FZ11: 0 | GA11: 0 | GB11: 0 | GC11: 0 | GD11: 0 | GE11: 0 | GF11: 0 | GG11: 0 | GH11: 0 | GI11: 0 | GJ11: 1 | GK11: 0 | GL11: 0 | GM11: 0 | GN11: 0 | GO11: 0 | GP11: 0 | GQ11: 1 | GR11: 0 | GS11: 0 | GT11: 0 | GU11: 0 | GV11: 0 | GW11: 0 | GX11: 0 | GY11: 0 | GZ11: 0 | HA11: 0 | HB11: 0 | HC11: 0 | HD11: 0 | HE11: 0 | HF11: 0 | HG11: 0 | HH11: 0 | HI11: 0 | HJ11: 0 | HK11: 0 | HL11: 0 | HM11: 0 | HN11: 0 | HO11: 0 | HP11: 0 | HQ11: 0 | HR11: 0 | HS11: 0 | HT11: 0 | HU11: 0 | HV11: 0 | HW11: 0 | HX11: 0 | HY11: 0 | HZ11: 0 | IA11: 0 | IB11: 0 | IC11: 0 | ID11: 0 | IE11: 0 | IF11: 0 | IG11: 0 | IH11: 0 | II11: 0 | IJ11: 0 | IK11: 0 | IL11: 1 | IM11: 0 | IN11: 0 | IO11: 0 | IP11: 0 | IQ11: 0 | IR11: 0 | IS11: 0 | IT11: 0 | IU11: 0 | IV11: 0 | IW11: 0 | IX11: 0 | IY11: 0 | IZ11: 0 | JA11: 0 | JB11: 0 | JC11: 1 | JD11: 0 | JE11: 0 | JF11: 1 | JG11: 0 | JH11: 0 | JI11: 0 | JJ11: 0 | JK11: 0 | JL11: 0 | JM11: 0 | JN11: 0 | JO11: 1 | JP11: 0 | JQ11: 0 | JR11: 0 | JS11: 0 | JT11: 0 | JU11: 0 | JV11: 0 | JW11: 0 | JX11: 0 | JY11: 0 | JZ11: 0 | KA11: 0 | KB11: 0 | KC11: 0 | KD11: 0 | KE11: 0 | KF11: 0 | KG11: 0 | KH11: 0 | KI11: 0 | KJ11: 0 | KK11: 0 | KL11: 0 | KM11: 0 | KN11: 0 | KO11: 0 | KP11: 0 | KQ11: 0 | KR11: 0 | KS11: 0 | KT11: 0 | KU11: 0 | KV11: 0 | KW11: 0 | KX11: 0 | KY11: 0 | KZ11: 0 | LA11: 0 | LB11: 0 | LC11: 0 | LD11: 0 | LE11: 0 | LF11: 0 | LG11: 0 | LH11: 0 | LI11: 0 | LJ11: 0 | LK11: 0 | LL11: 0 | LM11: 0 | LN11: 0 | LO11: 0 | LP11: 0 | LQ11: 0 | LR11: 0 | LS11: 0 | LT11: 0 | LU11: 0 | LV11: 0 | LW11: 0 | LX11: 0 | LY11: 0 | LZ11: 0 | MA11: 0 | MB11: 0 | MC11: 0 | MD11: 0 | ME11: 0 | MF11: 0 | MG11: 0 | MH11: 0 | MI11: 0 | MJ11: 0 | MK11: 0 | ML11: 0 | MM11: 0 | MN11: 0 | MO11: 0 | MP11: 0 | MQ11: 0 | MR11: 0 | MS11: 0 | MT11: 0 | MU11: 0 | MV11: 0 | MW11: 0 | MX11: 0 | MY11: 0 | MZ11: 0 | NA11: 0 | NB11: 0 | NC11: 0 | ND11: 0 | NE11: 0 | NF11: 1 | NG11: 0 | NH11: 0 | NI11: 0 | NJ11: 0 | NK11: 0 | NL11: 0 | NM11: 0 | NN11: 0 | NO11: 0 | NP11: 0 | NQ11: 0 | NR11: 0 | NS11: 0 | NT11: 0 | NU11: 0 | NV11: 0 | NW11: 0 | NX11: 0 | NY11: 0 | NZ11: 0 | OA11: 0 | OB11: 0 | OC11: 1 | OD11: 0 | OE11: 0 | OF11: 0 | OG11: 0 | OH11: 0 | OI11: 0 | OJ11: 0 | OK11: 0 | OL11: 0 | OM11: 0 | ON11: 0 | OO11: 0 | OP11: 1 | OQ11: 0 | OR11: 0 | OS11: 0 | OT11: 0 | OU11: 0 | OV11: 0 | OW11: 0 | OX11: 0 | OY11: 0 | OZ11: 0 | PA11: 0 | PB11: 0 | PC11: 0 | PD11: 0 | PE11: 0 | PF11: 1 | PG11: 0 | PH11: 0 | PI11: 0 | PJ11: 0 | PK11: 0 | PL11: 0 | PM11: 0 | PN11: 0 | PO11: 0 | PP11: 0 | PQ11: 0 | PR11: 0 | PS11: 0 | PT11: 0 | PU11: 0 | PV11: 0 | PW11: 1 | PX11: 0 | PY11: 0 | PZ11: 0 | QA11: 0 | QB11: 0 | QC11: 0 | QD11: 0 | QE11: 0 | QF11: 0 | QG11: 0 | QH11: 0 | QI11: 0 | QJ11: 0 | QK11: 0 | QL11: 0 | QM11: 0 | QN11: 0 | QO11: 0 | QP11: 0 | QQ11: 0 | QR11: 0 | QS11: 0 | QT11: 0 | QU11: 0 | QV11: 0 | QW11: 0 | QX11: 0 | QY11: 0 | QZ11: 0 | RA11: 0 | RB11: 0 | RC11: 0 | RD11: 0 | RE11: 0 | RF11: 0 | RG11: 0 | RH11: 0 | RI11: 0 | RJ11: 0 | RK11: 0 | RL11: 0 | RM11: 0 | RN11: 0 | RO11: 0 | RP11: 0 | RQ11: 0 | RR11: 0 | RS11: 0 | RT11: 0 | RU11: 0 | RV11: 0 | RW11: 0 | RX11: 0 | RY11: 0 | RZ11: 0 | SA11: 0 | SB11: 0 | SC11: 0 | SD11: 0 | SE11: 0 | SF11: 0 | SG11: 0 | SH11: 0 | SI11: 0 | SJ11: 0 | SK11: 0
A12: 5 | B12: {aneh} | C12: {D5,D85,D88,D148,D220,D295,D406,D411} | D12: =SUM(F12:SK12) -> 8 | E12: =SUMPRODUCT(F12:SK12,$F$5:$SK$5) -> 1.9760656 | F12: 0 | G12: 0 | H12: 0 | I12: 0 | J12: 1 | K12: 0 | L12: 0 | M12: 0 | N12: 0 | O12: 0 | P12: 0 | Q12: 0 | R12: 0 | S12: 0 | T12: 0 | U12: 0 | V12: 0 | W12: 0 | X12: 0 | Y12: 0 | Z12: 0 | AA12: 0 | AB12: 0 | AC12: 0 | AD12: 0 | AE12: 0 | AF12: 0 | AG12: 0 | AH12: 0 | AI12: 0 | AJ12: 0 | AK12: 0 | AL12: 0 | AM12: 0 | AN12: 0 | AO12: 0 | AP12: 0 | AQ12: 0 | AR12: 0 | AS12: 0 | AT12: 0 | AU12: 0 | AV12: 0 | AW12: 0 | AX12: 0 | AY12: 0 | AZ12: 0 | BA12: 0 | BB12: 0 | BC12: 0 | BD12: 0 | BE12: 0 | BF12: 0 | BG12: 0 | BH12: 0 | BI12: 0 | BJ12: 0 | BK12: 0 | BL12: 0 | BM12: 0 | BN12: 0 | BO12: 0 | BP12: 0 | BQ12: 0 | BR12: 0 | BS12: 0 | BT12: 0 | BU12: 0 | BV12: 0 | BW12: 0 | BX12: 0 | BY12: 0 | BZ12: 0 | CA12: 0 | CB12: 0 | CC12: 0 | CD12: 0 | CE12: 0 | CF12: 0 | CG12: 0 | CH12: 0 | CI12: 0 | CJ12: 0 | CK12: 0 | CL12: 1 | CM12: 0 | CN12: 0 | CO12: 1 | CP12: 0 | CQ12: 0 | CR12: 0 | CS12: 0 | CT12: 0 | CU12: 0 | CV12: 0 | CW12: 0 | CX12: 0 | CY12: 0 | CZ12: 0 | DA12: 0 | DB12: 0 | DC12: 0 | DD12: 0 | DE12: 0 | DF12: 0 | DG12: 0 | DH12: 0 | DI12: 0 | DJ12: 0 | DK12: 0 | DL12: 0 | DM12: 0 | DN12: 0 | DO12: 0 | DP12: 0 | DQ12: 0 | DR12: 0 | DS12: 0 | DT12: 0 | DU12: 0 | DV12: 0 | DW12: 0 | DX12: 0 | DY12: 0 | DZ12: 0 | EA12: 0 | EB12: 0 | EC12: 0 | ED12: 0 | EE12: 0 | EF12: 0 | EG12: 0 | EH12: 0 | EI12: 0 | EJ12: 0 | EK12: 0 | EL12: 0 | EM12: 0 | EN12: 0 | EO12: 0 | EP12: 0 | EQ12: 0 | ER12: 0 | ES12: 0 | ET12: 0 | EU12: 0 | EV12: 0 | EW12: 1 | EX12: 0 | EY12: 0 | EZ12: 0 | FA12: 0 | FB12: 0 | FC12: 0 | FD12: 0 | FE12: 0 | FF12: 0 | FG12: 0 | FH12: 0 | FI12: 0 | FJ12: 0 | FK12: 0 | FL12: 0 | FM12: 0 | FN12: 0 | FO12: 0 | FP12: 0 | FQ12: 0 | FR12: 0 | FS12: 0 | FT12: 0 | FU12: 0 | FV12: 0 | FW12: 0 | FX12: 0 | FY12: 0 | FZ12: 0 | GA12: 0 | GB12: 0 | GC12: 0 | GD12: 0 | GE12: 0 | GF12: 0 | GG12: 0 | GH12: 0 | GI12: 0 | GJ12: 0 | GK12: 0 | GL12: 0 | GM12: 0 | GN12: 0 | GO12: 0 | GP12: 0 | GQ12: 0 | GR12: 0 | GS12: 0 | GT12: 0 | GU12: 0 | GV12: 0 | GW12: 0 | GX12: 0 | GY12: 0 | GZ12: 0 | HA12: 0 | HB12: 0 | HC12: 0 | HD12: 0 | HE12: 0 | HF12: 0 | HG12: 0 | HH12: 0 | HI12: 0 | HJ12: 0 | HK12: 0 | HL12: 0 | HM12: 0 | HN12: 0 | HO12: 0 | HP12: 0 | HQ12: 1 | HR12: 0 | HS12: 0 | HT12: 0 | HU12: 0 | HV12: 0 | HW12: 0 | HX12: 0 | HY12: 0 | HZ12: 0 | IA12: 0 | IB12: 0 | IC12: 0 | ID12: 0 | IE12: 0 | IF12: 0 | IG12: 0 | IH12: 0 | II12: 0 | IJ12: 0 | IK12: 0 | IL12: 0 | IM12: 0 | IN12: 0 | IO12: 0 | IP12: 0 | IQ12: 0 | IR12: 0 | IS12: 0 | IT12: 0 | IU12: 0 | IV12: 0 | IW12: 0 | IX12: 0 | IY12: 0 | IZ12: 0 | JA12: 0 | JB12: 0 | JC12: 0 | JD12: 0 | JE12: 0 | JF12: 0 | JG12: 0 | JH12: 0 | JI12: 0 | JJ12: 0 | JK12: 0 | JL12: 0 | JM12: 0 | JN12: 0 | JO12: 0 | JP12: 0 | JQ12: 0 | JR12: 0 | JS12: 0 | JT12: 0 | JU12: 0 | JV12: 0 | JW12: 0 | JX12: 0 | JY12: 0 | JZ12: 0 | KA12: 0 | KB12: 0 | KC12: 0 | KD12: 0 | KE12: 0 | KF12: 0 | KG12: 0 | KH12: 0 | KI12: 0 | KJ12: 0 | KK12: 0 | KL12: 0 | KM12: 0 | KN12: 1 | KO12: 0 | KP12: 0 | KQ12: 0 | KR12: 0 | KS12: 0 | KT12: 0 | KU12: 0 | KV12: 0 | KW12: 0 | KX12: 0 | KY12: 0 | KZ12: 0 | LA12: 0 | LB12: 0 | LC12: 0 | LD12: 0 | LE12: 0 | LF12: 0 | LG12: 0 | LH12: 0 | LI12: 0 | LJ12: 0 | LK12: 0 | LL12: 0 | LM12: 0 | LN12: 0 | LO12: 0 | LP12: 0 | LQ12: 0 | LR12: 0 | LS12: 0 | LT12: 0 | LU12: 0 | LV12: 0 | LW12: 0 | LX12: 0 | LY12: 0 | LZ12: 0 | MA12: 0 | MB12: 0 | MC12: 0 | MD12: 0 | ME12: 0 | MF12: 0 | MG12: 0 | MH12: 0 | MI12: 0 | MJ12: 0 | MK12: 0 | ML12: 0 | MM12: 0 | MN12: 0 | MO12: 0 | MP12: 0 | MQ12: 0 | MR12: 0 | MS12: 0 | MT12: 0 | MU12: 0 | MV12: 0 | MW12: 0 | MX12: 0 | MY12: 0 | MZ12: 0 | NA12: 0 | NB12: 0 | NC12: 0 | ND12: 0 | NE12: 0 | NF12: 0 | NG12: 0 | NH12: 0 | NI12: 0 | NJ12: 0 | NK12: 0 | NL12: 0 | NM12: 0 | NN12: 0 | NO12: 0 | NP12: 0 | NQ12: 0 | NR12: 0 | NS12: 0 | NT12: 0 | NU12: 0 | NV12: 0 | NW12: 0 | NX12: 0 | NY12: 0 | NZ12: 0 | OA12: 0 | OB12: 0 | OC12: 0 | OD12: 0 | OE12: 0 | OF12: 0 | OG12: 0 | OH12: 0 | OI12: 0 | OJ12: 0 | OK12: 0 | OL12: 0 | OM12: 0 | ON12: 0 | OO12: 0 | OP12: 0 | OQ12: 0 | OR12: 0 | OS12: 0 | OT12: 0 | OU12: 1 | OV12: 0 | OW12: 0 | OX12: 0 | OY12: 0 | OZ12: 1 | PA12: 0 | PB12: 0 | PC12: 0 | PD12: 0 | PE12: 0 | PF12: 0 | PG12: 0 | PH12: 0 | PI12: 0 | PJ12: 0 | PK12: 0 | PL12: 0 | PM12: 0 | PN12: 0 | PO12: 0 | PP12: 0 | PQ12: 0 | PR12: 0 | PS12: 0 | PT12: 0 | PU12: 0 | PV12: 0 | PW12: 0 | PX12: 0 | PY12: 0 | PZ12: 0 | QA12: 0 | QB12: 0 | QC12: 0 | QD12: 0 | QE12: 0 | QF12: 0 | QG12: 0 | QH12: 0 | QI12: 0 | QJ12: 0 | QK12: 0 | QL12: 0 | QM12: 0 | QN12: 0 | QO12: 0 | QP12: 0 | QQ12: 0 | QR12: 0 | QS12: 0 | QT12: 0 | QU12: 0 | QV12: 0 | QW12: 0 | QX12: 0 | QY12: 0 | QZ12: 0 | RA12: 0 | RB12: 0 | RC12: 0 | RD12: 0 | RE12: 0 | RF12: 0 | RG12: 0 | RH12: 0 | RI12: 0 | RJ12: 0 | RK12: 0 | RL12: 0 | RM12: 0 | RN12: 0 | RO12: 0 | RP12: 0 | RQ12: 0 | RR12: 0 | RS12: 0 | RT12: 0 | RU12: 0 | RV12: 0 | RW12: 0 | RX12: 0 | RY12: 0 | RZ12: 0 | SA12: 0 | SB12: 0 | SC12: 0 | SD12: 0 | SE12: 0 | SF12: 0 | SG12: 0 | SH12: 0 | SI12: 0 | SJ12: 0 | SK12: 0
A13: 6 | B13: {apa} | C13: {D21,D62,D80,D85,D118,D160,D163,D176,D189,D190,D209,D235,D239,D270,D335,D336,D367,D419,D425,D490,D494} | D13: =SUM(F13:SK13) -> 21 | E13: =SUMPRODUCT(F13:SK13,$F$5:$SK$5) -> 5.8327031 | F13: 0 | G13: 0 | H13: 0 | I13: 0 | J13: 0 | K13: 0 | L13: 0 | M13: 0 | N13: 0 | O13: 0 | P13: 0 | Q13: 0 | R13: 0 | S13: 0 | T13: 0 | U13: 0 | V13: 0 | W13: 0 | X13: 0 | Y13: 0 | Z13: 1 | AA13: 0 | AB13: 0 | AC13: 0 | AD13: 0 | AE13: 0 | AF13: 0 | AG13: 0 | AH13: 0 | AI13: 0 | AJ13: 0 | AK13: 0 | AL13: 0 | AM13: 0 | AN13: 0 | AO13: 0 | AP13: 0 | AQ13: 0 | AR13: 0 | AS13: 0 | AT13: 0 | AU13: 0 | AV13: 0 | AW13: 0 | AX13: 0 | AY13: 0 | AZ13: 0 | BA13: 0 | BB13: 0 | BC13: 0 | BD13: 0 | BE13: 0 | BF13: 0 | BG13: 0 | BH13: 0 | BI13: 0 | BJ13: 0 | BK13: 0 | BL13: 0 | BM13: 0 | BN13: 0 | BO13: 1 | BP13: 0 | BQ13: 0 | BR13: 0 | BS13: 0 | BT13: 0 | BU13: 0 | BV13: 0 | BW13: 0 | BX13: 0 | BY13: 0 | BZ13: 0 | CA13: 0 | CB13: 0 | CC13: 0 | CD13: 0 | CE13: 0 | CF13: 0 | CG13: 1 | CH13: 0 | CI13: 0 | CJ13: 0 | CK13: 0 | CL13: 1 | CM13: 0 | CN13: 0 | CO13: 0 | CP13: 0 | CQ13: 0 | CR13: 0 | CS13: 0 | CT13: 0 | CU13: 0 | CV13: 0 | CW13: 0 | CX13: 0 | CY13: 0 | CZ13: 0 | DA13: 0 | DB13: 0 | DC13: 0 | DD13: 0 | DE13: 0 | DF13: 0 | DG13: 0 | DH13: 0 | DI13: 0 | DJ13: 0 | DK13: 0 | DL13: 0 | DM13: 0 | DN13: 0 | DO13: 0 | DP13: 0 | DQ13: 0 | DR13: 0 | DS13: 1 | DT13: 0 | DU13: 0 | DV13: 0 | DW13: 0 | DX13: 0 | DY13: 0 | DZ13: 0 | EA13: 0 | EB13: 0 | EC13: 0 | ED13: 0 | EE13: 0 | EF13: 0 | EG13: 0 | EH13: 0 | EI13: 0 | EJ13: 0 | EK13: 0 | EL13: 0 | EM13: 0 | EN13: 0 | EO13: 0 | EP13: 0 | EQ13: 0 | ER13: 0 | ES13: 0 | ET13: 0 | EU13: 0 | EV13: 0 | EW13: 0 | EX13: 0 | EY13: 0 | EZ13: 0 | FA13: 0 | FB13: 0 | FC13: 0 | FD13: 0 | FE13: 0 | FF13: 0 | FG13: 0 | FH13: 0 | FI13: 1 | FJ13: 0 | FK13: 0 | FL13: 1 | FM13: 0 | FN13: 0 | FO13: 0 | FP13: 0 | FQ13: 0 | FR13: 0 | FS13: 0 | FT13: 0 | FU13: 0 | FV13: 0 | FW13: 0 | FX13: 0 | FY13: 1 | FZ13: 0 | GA13: 0 | GB13: 0 | GC13: 0 | GD13: 0 | GE13: 0 | GF13: 0 | GG13: 0 | GH13: 0 | GI13: 0 | GJ13: 0 | GK13: 0 | GL13: 1 | GM13: 1 | GN13: 0 | GO13: 0 | GP13: 0 | GQ13: 0 | GR13: 0 | GS13: 0 | GT13: 0 | GU13: 0 | GV13: 0 | GW13: 0 | GX13: 0 | GY13: 0 | GZ13: 0 | HA13: 0 | HB13: 0 | HC13: 0 | HD13: 0 | HE13: 0 | HF13: 1 | HG13: 0 | HH13: 0 | HI13: 0 | HJ13: 0 | HK13: 0 | HL13: 0 | HM13: 0 | HN13: 0 | HO13: 0 | HP13: 0 | HQ13: 0 | HR13: 0 | HS13: 0 | HT13: 0 | HU13: 0 | HV13: 0 | HW13: 0 | HX13: 0 | HY13: 0 | HZ13: 0 | IA13: 0 | IB13: 0 | IC13: 0 | ID13: 0 | IE13: 0 | IF13: 1 | IG13: 0 | IH13: 0 | II13: 0 | IJ13: 1 | IK13: 0 | IL13: 0 | IM13: 0 | IN13: 0 | IO13: 0 | IP13: 0 | IQ13: 0 | IR13: 0 | IS13: 0 | IT13: 0 | IU13: 0 | IV13: 0 | IW13: 0 | IX13: 0 | IY13: 0 | IZ13: 0 | JA13: 0 | JB13: 0 | JC13: 0 | JD13: 0 | JE13: 0 | JF13: 0 | JG13: 0 | JH13: 0 | JI13: 0 | JJ13: 0 | JK13: 0 | JL13: 0 | JM13: 0 | JN13: 0 | JO13: 1 | JP13: 0 | JQ13: 0 | JR13: 0 | JS13: 0 | JT13: 0 | JU13: 0 | JV13: 0 | JW13: 0 | JX13: 0 | JY13: 0 | JZ13: 0 | KA13: 0 | KB13: 0 | KC13: 0 | KD13: 0 | KE13: 0 | KF13: 0 | KG13: 0 | KH13: 0 | KI13: 0 | KJ13: 0 | KK13: 0 | KL13: 0 | KM13: 0 | KN13: 0 | KO13: 0 | KP13: 0 | KQ13: 0 | KR13: 0 | KS13: 0 | KT13: 0 | KU13: 0 | KV13: 0 | KW13: 0 | KX13: 0 | KY13: 0 | KZ13: 0 | LA13: 0 | LB13: 0 | LC13: 0 | LD13: 0 | LE13: 0 | LF13: 0 | LG13: 0 | LH13: 0 | LI13: 0 | LJ13: 0 | LK13: 0 | LL13: 0 | LM13: 0 | LN13: 0 | LO13: 0 | LP13: 0 | LQ13: 0 | LR13: 0 | LS13: 0 | LT13: 0 | LU13: 0 | LV13: 0 | LW13: 0 | LX13: 0 | LY13: 0 | LZ13: 0 | MA13: 0 | MB13: 1 | MC13: 1 | MD13: 0 | ME13: 0 | MF13: 0 | MG13: 0 | MH13: 0 | MI13: 0 | MJ13: 0 | MK13: 0 | ML13: 0 | MM13: 0 | MN13: 0 | MO13: 0 | MP13: 0 | MQ13: 0 | MR13: 0 | MS13: 0 | MT13: 0 | MU13: 0 | MV13: 0 | MW13: 0 | MX13: 0 | MY13: 0 | MZ13: 0 | NA13: 0 | NB13: 0 | NC13: 0 | ND13: 0 | NE13: 0 | NF13: 0 | NG13: 0 | NH13: 1 | NI13: 0 | NJ13: 0 | NK13: 0 | NL13: 0 | NM13: 0 | NN13: 0 | NO13: 0 | NP13: 0 | NQ13: 0 | NR13: 0 | NS13: 0 | NT13: 0 | NU13: 0 | NV13: 0 | NW13: 0 | NX13: 0 | NY13: 0 | NZ13: 0 | OA13: 0 | OB13: 0 | OC13: 0 | OD13: 0 | OE13: 0 | OF13: 0 | OG13: 0 | OH13: 0 | OI13: 0 | OJ13: 0 | OK13: 0 | OL13: 0 | OM13: 0 | ON13: 0 | OO13: 0 | OP13: 0 | OQ13: 0 | OR13: 0 | OS13: 0 | OT13: 0 | OU13: 0 | OV13: 0 | OW13: 0 | OX13: 0 | OY13: 0 | OZ13: 0 | PA13: 0 | PB13: 0 | PC13: 0 | PD13: 0 | PE13: 0 | PF13: 0 | PG13: 0 | PH13: 1 | PI13: 0 | PJ13: 0 | PK13: 0 | PL13: 0 | PM13: 0 | PN13: 1 | PO13: 0 | PP13: 0 | PQ13: 0 | PR13: 0 | PS13: 0 | PT13: 0 | PU13: 0 | PV13: 0 | PW13: 0 | PX13: 0 | PY13: 0 | PZ13: 0 | QA13: 0 | QB13: 0 | QC13: 0 | QD13: 0 | QE13: 0 | QF13: 0 | QG13: 0 | QH13: 0 | QI13: 0 | QJ13: 0 | QK13: 0 | QL13: 0 | QM13: 0 | QN13: 0 | QO13: 0 | QP13: 0 | QQ13: 0 | QR13: 0 | QS13: 0 | QT13: 0 | QU13: 0 | QV13: 0 | QW13: 0 | QX13: 0 | QY13: 0 | QZ13: 0 | RA13: 0 | RB13: 0 | RC13: 0 | RD13: 0 | RE13: 0 | RF13: 0 | RG13: 0 | RH13: 0 | RI13: 0 | RJ13: 0 | RK13: 0 | RL13: 0 | RM13: 0 | RN13: 0 | RO13: 0 | RP13: 0 | RQ13: 0 | RR13: 0 | RS13: 0 | RT13: 0 | RU13: 0 | RV13: 0 | RW13: 0 | RX13: 0 | RY13: 0 | RZ13: 0 | SA13: 1 | SB13: 0 | SC13: 0 | SD13: 0 | SE13: 1 | SF13: 0 | SG13: 0 | SH13: 0 | SI13: 0 | SJ13: 0 | SK13: 0
A14: 7 | B14: {baik} | C14: {D14,D19,D40,D48,D68,D101,D132,D173,D207,D259,D264,D318,D346,D373,D453,D483} | D14: =SUM(F14:SK14) -> 16 | E14: =SUMPRODUCT(F14:SK14,$F$5:$SK$5) -> 4.2736624 | F14: 0 | G14: 0 | H14: 0 | I14: 0 | J14: 0 | K14: 0 | L14: 0 | M14: 0 | N14: 0 | O14: 0 | P14: 0 | Q14: 0 | R14: 0 | S14: 1 | T14: 0 | U14: 0 | V14: 0 | W14: 0 | X14: 1 | Y14: 0 | Z14: 0 | AA14: 0 | AB14: 0 | AC14: 0 | AD14: 0 | AE14: 0 | AF14: 0 | AG14: 0 | AH14: 0 | AI14: 0 | AJ14: 0 | AK14: 0 | AL14: 0 | AM14: 0 | AN14: 0 | AO14: 0 | AP14: 0 | AQ14: 0 | AR14: 0 | AS14: 1 | AT14: 0 | AU14: 0 | AV14: 0 | AW14: 0 | AX14: 0 | AY14: 0 | AZ14: 0 | BA14: 1 | BB14: 0 | BC14: 0 | BD14: 0 | BE14: 0 | BF14: 0 | BG14: 0 | BH14: 0 | BI14: 0 | BJ14: 0 | BK14: 0 | BL14: 0 | BM14: 0 | BN14: 0 | BO14: 0 | BP14: 0 | BQ14: 0 | BR14: 0 | BS14: 0 | BT14: 0 | BU14: 1 | BV14: 0 | BW14: 0 | BX14: 0 | BY14: 0 | BZ14: 0 | CA14: 0 | CB14: 0 | CC14: 0 | CD14: 0 | CE14: 0 | CF14: 0 | CG14: 0 | CH14: 0 | CI14: 0 | CJ14: 0 | CK14: 0 | CL14: 0 | CM14: 0 | CN14: 0 | CO14: 0 | CP14: 0 | CQ14: 0 | CR14: 0 | CS14: 0 | CT14: 0 | CU14: 0 | CV14: 0 | CW14: 0 | CX14: 0 | CY14: 0 | CZ14: 0 | DA14: 0 | DB14: 1 | DC14: 0 | DD14: 0 | DE14: 0 | DF14: 0 | DG14: 0 | DH14: 0 | DI14: 0 | DJ14: 0 | DK14: 0 | DL14: 0 | DM14: 0 | DN14: 0 | DO14: 0 | DP14: 0 | DQ14: 0 | DR14: 0 | DS14: 0 | DT14: 0 | DU14: 0 | DV14: 0 | DW14: 0 | DX14: 0 | DY14: 0 | DZ14: 0 | EA14: 0 | EB14: 0 | EC14: 0 | ED14: 0 | EE14: 0 | EF14: 0 | EG14: 1 | EH14: 0 | EI14: 0 | EJ14: 0 | EK14: 0 | EL14: 0 | EM14: 0 | EN14: 0 | EO14: 0 | EP14: 0 | EQ14: 0 | ER14: 0 | ES14: 0 | ET14: 0 | EU14: 0 | EV14: 0 | EW14: 0 | EX14: 0 | EY14: 0 | EZ14: 0 | FA14: 0 | FB14: 0 | FC14: 0 | FD14: 0 | FE14: 0 | FF14: 0 | FG14: 0 | FH14: 0 | FI14: 0 | FJ14: 0 | FK14: 0 | FL14: 0 | FM14: 0 | FN14: 0 | FO14: 0 | FP14: 0 | FQ14: 0 | FR14: 0 | FS14: 0 | FT14: 0 | FU14: 0 | FV14: 1 | FW14: 0 | FX14: 0 | FY14: 0 | FZ14: 0 | GA14: 0 | GB14: 0 | GC14: 0 | GD14: 0 | GE14: 0 | GF14: 0 | GG14: 0 | GH14: 0 | GI14: 0 | GJ14: 0 | GK14: 0 | GL14: 0 | GM14: 0 | GN14: 0 | GO14: 0 | GP14: 0 | GQ14: 0 | GR14: 0 | GS14: 0 | GT14: 0 | GU14: 0 | GV14: 0 | GW14: 0 | GX14: 0 | GY14: 0 | GZ14: 0 | HA14: 0 | HB14: 0 | HC14: 0 | HD14: 1 | HE14: 0 | HF14: 0 | HG14: 0 | HH14: 0 | HI14: 0 | HJ14: 0 | HK14: 0 | HL14: 0 | HM14: 0 | HN14: 0 | HO14: 0 | HP14: 0 | HQ14: 0 | HR14: 0 | HS14: 0 | HT14: 0 | HU14: 0 | HV14: 0 | HW14: 0 | HX14: 0 | HY14: 0 | HZ14: 0 | IA14: 0 | IB14: 0 | IC14: 0 | ID14: 0 | IE14: 0 | IF14: 0 | IG14: 0 | IH14: 0 | II14: 0 | IJ14: 0 | IK14: 0 | IL14: 0 | IM14: 0 | IN14: 0 | IO14: 0 | IP14: 0 | IQ14: 0 | IR14: 0 | IS14: 0 | IT14: 0 | IU14: 0 | IV14: 0 | IW14: 0 | IX14: 0 | IY14: 0 | IZ14: 0 | JA14: 0 | JB14: 0 | JC14: 0 | JD14: 1 | JE14: 0 | JF14: 0 | JG14: 0 | JH14: 0 | JI14: 1 | JJ14: 0 | JK14: 0 | JL14: 0 | JM14: 0 | JN14: 0 | JO14: 0 | JP14: 0 | JQ14: 0 | JR14: 0 | JS14: 0 | JT14: 0 | JU14: 0 | JV14: 0 | JW14: 0 | JX14: 0 | JY14: 0 | JZ14: 0 | KA14: 0 | KB14: 0 | KC14: 0 | KD14: 0 | KE14: 0 | KF14: 0 | KG14: 0 | KH14: 0 | KI14: 0 | KJ14: 0 | KK14: 0 | KL14: 0 | KM14: 0 | KN14: 0 | KO14: 0 | KP14: 0 | KQ14: 0 | KR14: 0 | KS14: 0 | KT14: 0 | KU14: 0 | KV14: 0 | KW14: 0 | KX14: 0 | KY14: 0 | KZ14: 0 | LA14: 0 | LB14: 0 | LC14: 0 | LD14: 0 | LE14: 0 | LF14: 0 | LG14: 0 | LH14: 0 | LI14: 0 | LJ14: 0 | LK14: 1 | LL14: 0 | LM14: 0 | LN14: 0 | LO14: 0 | LP14: 0 | LQ14: 0 | LR14: 0 | LS14: 0 | LT14: 0 | LU14: 0 | LV14: 0 | LW14: 0 | LX14: 0 | LY14: 0 | LZ14: 0 | MA14: 0 | MB14: 0 | MC14: 0 | MD14: 0 | ME14: 0 | MF14: 0 | MG14: 0 | MH14: 0 | MI14: 0 | MJ14: 0 | MK14: 0 | ML14: 0 | MM14: 1 | MN14: 0 | MO14: 0 | MP14: 0 | MQ14: 0 | MR14: 0 | MS14: 0 | MT14: 0 | MU14: 0 | MV14: 0 | MW14: 0 | MX14: 0 | MY14: 0 | MZ14: 0 | NA14: 0 | NB14: 0 | NC14: 0 | ND14: 0 | NE14: 0 | NF14: 0 | NG14: 0 | NH14: 0 | NI14: 0 | NJ14: 0 | NK14: 0 | NL14: 0 | NM14: 0 | NN14: 1 | NO14: 0 | NP14: 0 | NQ14: 0 | NR14: 0 | NS14: 0 | NT14: 0 | NU14: 0 | NV14: 0 | NW14: 0 | NX14: 0 | NY14: 0 | NZ14: 0 | OA14: 0 | OB14: 0 | OC14: 0 | OD14: 0 | OE14: 0 | OF14: 0 | OG14: 0 | OH14: 0 | OI14: 0 | OJ14: 0 | OK14: 0 | OL14: 0 | OM14: 0 | ON14: 0 | OO14: 0 | OP14: 0 | OQ14: 0 | OR14: 0 | OS14: 0 | OT14: 0 | OU14: 0 | OV14: 0 | OW14: 0 | OX14: 0 | OY14: 0 | OZ14: 0 | PA14: 0 | PB14: 0 | PC14: 0 | PD14: 0 | PE14: 0 | PF14: 0 | PG14: 0 | PH14: 0 | PI14: 0 | PJ14: 0 | PK14: 0 | PL14: 0 | PM14: 0 | PN14: 0 | PO14: 0 | PP14: 0 | PQ14: 0 | PR14: 0 | PS14: 0 | PT14: 0 | PU14: 0 | PV14: 0 | PW14: 0 | PX14: 0 | PY14: 0 | PZ14: 0 | QA14: 0 | QB14: 0 | QC14: 0 | QD14: 0 | QE14: 0 | QF14: 0 | QG14: 0 | QH14: 0 | QI14: 0 | QJ14: 0 | QK14: 0 | QL14: 0 | QM14: 0 | QN14: 0 | QO14: 0 | QP14: 1 | QQ14: 0 | QR14: 0 | QS14: 0 | QT14: 0 | QU14: 0 | QV14: 0 | QW14: 0 | QX14: 0 | QY14: 0 | QZ14: 0 | RA14: 0 | RB14: 0 | RC14: 0 | RD14: 0 | RE14: 0 | RF14: 0 | RG14: 0 | RH14: 0 | RI14: 0 | RJ14: 0 | RK14: 0 | RL14: 0 | RM14: 0 | RN14: 0 | RO14: 0 | RP14: 0 | RQ14: 0 | RR14: 0 | RS14: 0 | RT14: 1 | RU14: 0 | RV14: 0 | RW14: 0 | RX14: 0 | RY14: 0 | RZ14: 0 | SA14: 0 | SB14: 0 | SC14: 0 | SD14: 0 | SE14: 0 | SF14: 0 | SG14: 0 | SH14: 0 | SI14: 0 | SJ14: 0 | SK14: 0
A15: 8 | B15: {bang} | C15: {D28,D66,D126,D140,D188,D234,D243,D263,D296,D324,D394,D484} | D15: =SUM(F15:SK15) -> 12 | E15: =SUMPRODUCT(F15:SK15,$F$5:$SK$5) -> 3.9778621 | F15: 0 | G15: 0 | H15: 0 | I15: 0 | J15: 0 | K15: 0 | L15: 0 | M15: 0 | N15: 0 | O15: 0 | P15: 0 | Q15: 0 | R15: 0 | S15: 0 | T15: 0 | U15: 0 | V15: 0 | W15: 0 | X15: 0 | Y15: 0 | Z15: 0 | AA15: 0 | AB15: 0 | AC15: 0 | AD15: 0 | AE15: 0 | AF15: 0 | AG15: 1 | AH15: 0 | AI15: 0 | AJ15: 0 | AK15: 0 | AL15: 0 | AM15: 0 | AN15: 0 | AO15: 0 | AP15: 0 | AQ15: 0 | AR15: 0 | AS15: 0 | AT15: 0 | AU15: 0 | AV15: 0 | AW15: 0 | AX15: 0 | AY15: 0 | AZ15: 0 | BA15: 0 | BB15: 0 | BC15: 0 | BD15: 0 | BE15: 0 | BF15: 0 | BG15: 0 | BH15: 0 | BI15: 0 | BJ15: 0 | BK15: 0 | BL15: 0 | BM15: 0 | BN15: 0 | BO15: 0 | BP15: 0 | BQ15: 0 | BR15: 0 | BS15: 1 | BT15: 0 | BU15: 0 | BV15: 0 | BW15: 0 | BX15: 0 | BY15: 0 | BZ15: 0 | CA15: 0 | CB15: 0 | CC15: 0 | CD15: 0 | CE15: 0 | CF15: 0 | CG15: 0 | CH15: 0 | CI15: 0 | CJ15: 0 | CK15: 0 | CL15: 0 | CM15: 0 | CN15: 0 | CO15: 0 | CP15: 0 | CQ15: 0 | CR15: 0 | CS15: 0 | CT15: 0 | CU15: 0 | CV15: 0 | CW15: 0 | CX15: 0 | CY15: 0 | CZ15: 0 | DA15: 0 | DB15: 0 | DC15: 0 | DD15: 0 | DE15: 0 | DF15: 0 | DG15: 0 | DH15: 0 | DI15: 0 | DJ15: 0 | DK15: 0 | DL15: 0 | DM15: 0 | DN15: 0 | DO15: 0 | DP15: 0 | DQ15: 0 | DR15: 0 | DS15: 0 | DT15: 0 | DU15: 0 | DV15: 0 | DW15: 0 | DX15: 0 | DY15: 0 | DZ15: 0 | EA15: 1 | EB15: 0 | EC15: 0 | ED15: 0 | EE15: 0 | EF15: 0 | EG15: 0 | EH15: 0 | EI15: 0 | EJ15: 0 | EK15: 0 | EL15: 0 | EM15: 0 | EN15: 0 | EO15: 1 | EP15: 0 | EQ15: 0 | ER15: 0 | ES15: 0 | ET15: 0 | EU15: 0 | EV15: 0 | EW15: 0 | EX15: 0 | EY15: 0 | EZ15: 0 | FA15: 0 | FB15: 0 | FC15: 0 | FD15: 0 | FE15: 0 | FF15: 0 | FG15: 0 | FH15: 0 | FI15: 0 | FJ15: 0 | FK15: 0 | FL15: 0 | FM15: 0 | FN15: 0 | FO15: 0 | FP15: 0 | FQ15: 0 | FR15: 0 | FS15: 0 | FT15: 0 | FU15: 0 | FV15: 0 | FW15: 0 | FX15: 0 | FY15: 0 | FZ15: 0 | GA15: 0 | GB15: 0 | GC15: 0 | GD15: 0 | GE15: 0 | GF15: 0 | GG15: 0 | GH15: 0 | GI15: 0 | GJ15: 0 | GK15: 1 | GL15: 0 | GM15: 0 | GN15: 0 | GO15: 0 | GP15: 0 | GQ15: 0 | GR15: 0 | GS15: 0 | GT15: 0 | GU15: 0 | GV15: 0 | GW15: 0 | GX15: 0 | GY15: 0 | GZ15: 0 | HA15: 0 | HB15: 0 | HC15: 0 | HD15: 0 | HE15: 0 | HF15: 0 | HG15: 0 | HH15: 0 | HI15: 0 | HJ15: 0 | HK15: 0 | HL15: 0 | HM15: 0 | HN15: 0 | HO15: 0 | HP15: 0 | HQ15: 0 | HR15: 0 | HS15: 0 | HT15: 0 | HU15: 0 | HV15: 0 | HW15: 0 | HX15: 0 | HY15: 0 | HZ15: 0 | IA15: 0 | IB15: 0 | IC15: 0 | ID15: 0 | IE15: 1 | IF15: 0 | IG15: 0 | IH15: 0 | II15: 0 | IJ15: 0 | IK15: 0 | IL15: 0 | IM15: 0 | IN15: 1 | IO15: 0 | IP15: 0 | IQ15: 0 | IR15: 0 | IS15: 0 | IT15: 0 | IU15: 0 | IV15: 0 | IW15: 0 | IX15: 0 | IY15: 0 | IZ15: 0 | JA15: 0 | JB15: 0 | JC15: 0 | JD15: 0 | JE15: 0 | JF15: 0 | JG15: 0 | JH15: 1 | JI15: 0 | JJ15: 0 | JK15: 0 | JL15: 0 | JM15: 0 | JN15: 0 | JO15: 0 | JP15: 0 | JQ15: 0 | JR15: 0 | JS15: 0 | JT15: 0 | JU15: 0 | JV15: 0 | JW15: 0 | JX15: 0 | JY15: 0 | JZ15: 0 | KA15: 0 | KB15: 0 | KC15: 0 | KD15: 0 | KE15: 0 | KF15: 0 | KG15: 0 | KH15: 0 | KI15: 0 | KJ15: 0 | KK15: 0 | KL15: 0 | KM15: 0 | KN15: 0 | KO15: 1 | KP15: 0 | KQ15: 0 | KR15: 0 | KS15: 0 | KT15: 0 | KU15: 0 | KV15: 0 | KW15: 0 | KX15: 0 | KY15: 0 | KZ15: 0 | LA15: 0 | LB15: 0 | LC15: 0 | LD15: 0 | LE15: 0 | LF15: 0 | LG15: 0 | LH15: 0 | LI15: 0 | LJ15: 0 | LK15: 0 | LL15: 0 | LM15: 0 | LN15: 0 | LO15: 0 | LP15: 0 | LQ15: 1 | LR15: 0 | LS15: 0 | LT15: 0 | LU15: 0 | LV15: 0 | LW15: 0 | LX15: 0 | LY15: 0 | LZ15: 0 | MA15: 0 | MB15: 0 | MC15: 0 | MD15: 0 | ME15: 0 | MF15: 0 | MG15: 0 | MH15: 0 | MI15: 0 | MJ15: 0 | MK15: 0 | ML15: 0 | MM15: 0 | MN15: 0 | MO15: 0 | MP15: 0 | MQ15: 0 | MR15: 0 | MS15: 0 | MT15: 0 | MU15: 0 | MV15: 0 | MW15: 0 | MX15: 0 | MY15: 0 | MZ15: 0 | NA15: 0 | NB15: 0 | NC15: 0 | ND15: 0 | NE15: 0 | NF15: 0 | NG15: 0 | NH15: 0 | NI15: 0 | NJ15: 0 | NK15: 0 | NL15: 0 | NM15: 0 | NN15: 0 | NO15: 0 | NP15: 0 | NQ15: 0 | NR15: 0 | NS15: 0 | NT15: 0 | NU15: 0 | NV15: 0 | NW15: 0 | NX15: 0 | NY15: 0 | NZ15: 0 | OA15: 0 | OB15: 0 | OC15: 0 | OD15: 0 | OE15: 0 | OF15: 0 | OG15: 0 | OH15: 0 | OI15: 1 | OJ15: 0 | OK15: 0 | OL15: 0 | OM15: 0 | ON15: 0 | OO15: 0 | OP15: 0 | OQ15: 0 | OR15: 0 | OS15: 0 | OT15: 0 | OU15: 0 | OV15: 0 | OW15: 0 | OX15: 0 | OY15: 0 | OZ15: 0 | PA15: 0 | PB15: 0 | PC15: 0 | PD15: 0 | PE15: 0 | PF15: 0 | PG15: 0 | PH15: 0 | PI15: 0 | PJ15: 0 | PK15: 0 | PL15: 0 | PM15: 0 | PN15: 0 | PO15: 0 | PP15: 0 | PQ15: 0 | PR15: 0 | PS15: 0 | PT15: 0 | PU15: 0 | PV15: 0 | PW15: 0 | PX15: 0 | PY15: 0 | PZ15: 0 | QA15: 0 | QB15: 0 | QC15: 0 | QD15: 0 | QE15: 0 | QF15: 0 | QG15: 0 | QH15: 0 | QI15: 0 | QJ15: 0 | QK15: 0 | QL15: 0 | QM15: 0 | QN15: 0 | QO15: 0 | QP15: 0 | QQ15: 0 | QR15: 0 | QS15: 0 | QT15: 0 | QU15: 0 | QV15: 0 | QW15: 0 | QX15: 0 | QY15: 0 | QZ15: 0 | RA15: 0 | RB15: 0 | RC15: 0 | RD15: 0 | RE15: 0 | RF15: 0 | RG15: 0 | RH15: 0 | RI15: 0 | RJ15: 0 | RK15: 0 | RL15: 0 | RM15: 0 | RN15: 0 | RO15: 0 | RP15: 0 | RQ15: 0 | RR15: 0 | RS15: 0 | RT15: 0 | RU15: 1 | RV15: 0 | RW15: 0 | RX15: 0 | RY15: 0 | RZ15: 0 | SA15: 0 | SB15: 0 | SC15: 0 | SD15: 0 | SE15: 0 | SF15: 0 | SG15: 0 | SH15: 0 | SI15: 0 | SJ15: 0 | SK15: 0
A16: 9 | B16: {banyak} | C16: {D30,D60,D95,D113,D132,D156,D183,D186,D209,D218,D239,D270,D364,D413,D434,D494} | D16: =SUM(F16:SK16) -> 16 | E16: =SUMPRODUCT(F16:SK16,$F$5:$SK$5) -> 4.192626 | F16: 0 | G16: 0 | H16: 0 | I16: 0 | J16: 0 | K16: 0 | L16: 0 | M16: 0 | N16: 0 | O16: 0 | P16: 0 | Q16: 0 | R16: 0 | S16: 0 | T16: 0 | U16: 0 | V16: 0 | W16: 0 | X16: 0 | Y16: 0 | Z16: 0 | AA16: 0 | AB16: 0 | AC16: 0 | AD16: 0 | AE16: 0 | AF16: 0 | AG16: 0 | AH16: 0 | AI16: 1 | AJ16: 0 | AK16: 0 | AL16: 0 | AM16: 0 | AN16: 0 | AO16: 0 | AP16: 0 | AQ16: 0 | AR16: 0 | AS16: 0 | AT16: 0 | AU16: 0 | AV16: 0 | AW16: 0 | AX16: 0 | AY16: 0 | AZ16: 0 | BA16: 0 | BB16: 0 | BC16: 0 | BD16: 0 | BE16: 0 | BF16: 0 | BG16: 0 | BH16: 0 | BI16: 0 | BJ16: 0 | BK16: 0 | BL16: 0 | BM16: 1 | BN16: 0 | BO16: 0 | BP16: 0 | BQ16: 0 | BR16: 0 | BS16: 0 | BT16: 0 | BU16: 0 | BV16: 0 | BW16: 0 | BX16: 0 | BY16: 0 | BZ16: 0 | CA16: 0 | CB16: 0 | CC16: 0 | CD16: 0 | CE16: 0 | CF16: 0 | CG16: 0 | CH16: 0 | CI16: 0 | CJ16: 0 | CK16: 0 | CL16: 0 | CM16: 0 | CN16: 0 | CO16: 0 | CP16: 0 | CQ16: 0 | CR16: 0 | CS16: 0 | CT16: 0 | CU16: 0 | CV16: 1 | CW16: 0 | CX16: 0 | CY16: 0 | CZ16: 0 | DA16: 0 | DB16: 0 | DC16: 0 | DD16: 0 | DE16: 0 | DF16: 0 | DG16: 0 | DH16: 0 | DI16: 0 | DJ16: 0 | DK16: 0 | DL16: 0 | DM16: 0 | DN16: 1 | DO16: 0 | DP16: 0 | DQ16: 0 | DR16: 0 | DS16: 0 | DT16: 0 | DU16: 0 | DV16: 0 | DW16: 0 | DX16: 0 | DY16: 0 | DZ16: 0 | EA16: 0 | EB16: 0 | EC16: 0 | ED16: 0 | EE16: 0 | EF16: 0 | EG16: 1 | EH16: 0 | EI16: 0 | EJ16: 0 | EK16: 0 | EL16: 0 | EM16: 0 | EN16: 0 | EO16: 0 | EP16: 0 | EQ16: 0 | ER16: 0 | ES16: 0 | ET16: 0 | EU16: 0 | EV16: 0 | EW16: 0 | EX16: 0 | EY16: 0 | EZ16: 0 | FA16: 0 | FB16: 0 | FC16: 0 | FD16: 0 | FE16: 1 | FF16: 0 | FG16: 0 | FH16: 0 | FI16: 0 | FJ16: 0 | FK16: 0 | FL16: 0 | FM16: 0 | FN16: 0 | FO16: 0 | FP16: 0 | FQ16: 0 | FR16: 0 | FS16: 0 | FT16: 0 | FU16: 0 | FV16: 0 | FW16: 0 | FX16: 0 | FY16: 0 | FZ16: 0 | GA16: 0 | GB16: 0 | GC16: 0 | GD16: 0 | GE16: 0 | GF16: 1 | GG16: 0 | GH16: 0 | GI16: 1 | GJ16: 0 | GK16: 0 | GL16: 0 | GM16: 0 | GN16: 0 | GO16: 0 | GP16: 0 | GQ16: 0 | GR16: 0 | GS16: 0 | GT16: 0 | GU16: 0 | GV16: 0 | GW16: 0 | GX16: 0 | GY16: 0 | GZ16: 0 | HA16: 0 | HB16: 0 | HC16: 0 | HD16: 0 | HE16: 0 | HF16: 1 | HG16: 0 | HH16: 0 | HI16: 0 | HJ16: 0 | HK16: 0 | HL16: 0 | HM16: 0 | HN16: 0 | HO16: 1 | HP16: 0 | HQ16: 0 | HR16: 0 | HS16: 0 | HT16: 0 | HU16: 0 | HV16: 0 | HW16: 0 | HX16: 0 | HY16: 0 | HZ16: 0 | IA16: 0 | IB16: 0 | IC16: 0 | ID16: 0 | IE16: 0 | IF16: 0 | IG16: 0 | IH16: 0 | II16: 0 | IJ16: 1 | IK16: 0 | IL16: 0 | IM16: 0 | IN16: 0 | IO16: 0 | IP16: 0 | IQ16: 0 | IR16: 0 | IS16: 0 | IT16: 0 | IU16: 0 | IV16: 0 | IW16: 0 | IX16: 0 | IY16: 0 | IZ16: 0 | JA16: 0 | JB16: 0 | JC16: 0 | JD16: 0 | JE16: 0 | JF16: 0 | JG16: 0 | JH16: 0 | JI16: 0 | JJ16: 0 | JK16: 0 | JL16: 0 | JM16: 0 | JN16: 0 | JO16: 1 | JP16: 0 | JQ16: 0 | JR16: 0 | JS16: 0 | JT16: 0 | JU16: 0 | JV16: 0 | JW16: 0 | JX16: 0 | JY16: 0 | JZ16: 0 | KA16: 0 | KB16: 0 | KC16: 0 | KD16: 0 | KE16: 0 | KF16: 0 | KG16: 0 | KH16: 0 | KI16: 0 | KJ16: 0 | KK16: 0 | KL16: 0 | KM16: 0 | KN16: 0 | KO16: 0 | KP16: 0 | KQ16: 0 | KR16: 0 | KS16: 0 | KT16: 0 | KU16: 0 | KV16: 0 | KW16: 0 | KX16: 0 | KY16: 0 | KZ16: 0 | LA16: 0 | LB16: 0 | LC16: 0 | LD16: 0 | LE16: 0 | LF16: 0 | LG16: 0 | LH16: 0 | LI16: 0 | LJ16: 0 | LK16: 0 | LL16: 0 | LM16: 0 | LN16: 0 | LO16: 0 | LP16: 0 | LQ16: 0 | LR16: 0 | LS16: 0 | LT16: 0 | LU16: 0 | LV16: 0 | LW16: 0 | LX16: 0 | LY16: 0 | LZ16: 0 | MA16: 0 | MB16: 0 | MC16: 0 | MD16: 0 | ME16: 0 | MF16: 0 | MG16: 0 | MH16: 0 | MI16: 0 | MJ16: 0 | MK16: 0 | ML16: 0 | MM16: 0 | MN16: 0 | MO16: 0 | MP16: 0 | MQ16: 0 | MR16: 0 | MS16: 0 | MT16: 0 | MU16: 0 | MV16: 0 | MW16: 0 | MX16: 0 | MY16: 0 | MZ16: 0 | NA16: 0 | NB16: 0 | NC16: 0 | ND16: 0 | NE16: 1 | NF16: 0 | NG16: 0 | NH16: 0 | NI16: 0 | NJ16: 0 | NK16: 0 | NL16: 0 | NM16: 0 | NN16: 0 | NO16: 0 | NP16: 0 | NQ16: 0 | NR16: 0 | NS16: 0 | NT16: 0 | NU16: 0 | NV16: 0 | NW16: 0 | NX16: 0 | NY16: 0 | NZ16: 0 | OA16: 0 | OB16: 0 | OC16: 0 | OD16: 0 | OE16: 0 | OF16: 0 | OG16: 0 | OH16: 0 | OI16: 0 | OJ16: 0 | OK16: 0 | OL16: 0 | OM16: 0 | ON16: 0 | OO16: 0 | OP16: 0 | OQ16: 0 | OR16: 0 | OS16: 0 | OT16: 0 | OU16: 0 | OV16: 0 | OW16: 0 | OX16: 0 | OY16: 0 | OZ16: 0 | PA16: 0 | PB16: 1 | PC16: 0 | PD16: 0 | PE16: 0 | PF16: 0 | PG16: 0 | PH16: 0 | PI16: 0 | PJ16: 0 | PK16: 0 | PL16: 0 | PM16: 0 | PN16: 0 | PO16: 0 | PP16: 0 | PQ16: 0 | PR16: 0 | PS16: 0 | PT16: 0 | PU16: 0 | PV16: 0 | PW16: 1 | PX16: 0 | PY16: 0 | PZ16: 0 | QA16: 0 | QB16: 0 | QC16: 0 | QD16: 0 | QE16: 0 | QF16: 0 | QG16: 0 | QH16: 0 | QI16: 0 | QJ16: 0 | QK16: 0 | QL16: 0 | QM16: 0 | QN16: 0 | QO16: 0 | QP16: 0 | QQ16: 0 | QR16: 0 | QS16: 0 | QT16: 0 | QU16: 0 | QV16: 0 | QW16: 0 | QX16: 0 | QY16: 0 | QZ16: 0 | RA16: 0 | RB16: 0 | RC16: 0 | RD16: 0 | RE16: 0 | RF16: 0 | RG16: 0 | RH16: 0 | RI16: 0 | RJ16: 0 | RK16: 0 | RL16: 0 | RM16: 0 | RN16: 0 | RO16: 0 | RP16: 0 | RQ16: 0 | RR16: 0 | RS16: 0 | RT16: 0 | RU16: 0 | RV16: 0 | RW16: 0 | RX16: 0 | RY16: 0 | RZ16: 0 | SA16: 0 | SB16: 0 | SC16: 0 | SD16: 0 | SE16: 1 | SF16: 0 | SG16: 0 | SH16: 0 | SI16: 0 | SJ16: 0 | SK16: 0
